Workbook

Sheet Daftar Belanja
A1: DAFTAR KOMPONEN DEMO DAY — Purwarupa APFC 1 Fasa (Fase 1, meter CHINT DDSU666)
A2: DeepTech for Smart-X Hackathon 2026 · Harga dari penelusuran Tokopedia 2–4 Okt 2026 (belum termasuk ongkir). Teks biru = boleh diubah (Qty, harga). Kolom Status (kuning): Belum / Dipesan / Diterima / Sudah punya — 'Sudah punya' otomatis tidak dihitung di total.
A3: Kolom R 'Tahap beli': 1 = pesan hari ini · 2 = setelah uji meja · 3 = setelah pengumuman lolos. Rincian per tahap ada di sheet Tahap 1–3.
A4: No | B4: Kategori | C4: Komponen | D4: Merek / Model / Kode seri | E4: Spesifikasi kunci | F4: Qty | G4: Satuan | H4: Harga satuan min (Rp) | I4: Harga satuan maks (Rp) | J4: Subtotal min (Rp) | K4: Subtotal maks (Rp) | L4: Prioritas | M4: Sumber harga | N4: Harga Beli (RP) | O4: Status | P4: Link Tokopedia | Q4: Link Shopee | R4: Catatan agar tidak salah beli | S4: Tahap beli
A5: 1 | B5: A. Pengukuran & Kontrol | C5: Meter energi 1 fasa (Modbus) | D5: CHINT DDSU666 — varian RS485 Modbus, 5(80)A, 230V 1P2W | E5: Ukur V, I, P, Q, PF, Hz, kWh; RS485 Modbus-RTU; kelas 1; DIN rail 2 modul | F5: 1 | G5: unit | H5: 720000 | I5: 800000 | J5: =IF(O5="Sudah punya",0,F5*H5) -> 720000 | K5: =IF(O5="Sudah punya",0,F5*I5) -> 800000 | L5: Wajib | M5: Tokopedia (dicek 2–4 Okt 2026) | N5: 329999 | O5: Diterima | P5: Tokopedia | Q5: Shopee | R5: WAJIB ada tulisan 'RS485' di judul. Versi tanpa RS485 (±Rp410 rb) TIDAK bisa dibaca ESP32. Minta penjual foto terminal 24/25 (A/B). | S5: 1
A6: 2 | B6: A. Pengukuran & Kontrol | C6: Mikrokontroler / edge controller | D6: ESP32 DevKit V1 — modul ESP-WROOM-32, 30 pin, USB-C | E6: Dual-core 240 MHz, Wi-Fi + BLE, 4 MB flash, chip USB CP2102/CH340 | F6: 2 | G6: unit | H6: 65000 | I6: 100000 | J6: =IF(O6="Sudah punya",0,F6*H6) -> 0 | K6: =IF(O6="Sudah punya",0,F6*I6) -> 0 | L6: Wajib (1 cadangan) | M6: Tokopedia (dicek 2–4 Okt 2026) | O6: Sudah punya | P6: Tokopedia | Q6: Shopee | R6: Pilih WROOM-32 (bukan WROVER — GPIO16/17 dipakai PSRAM). Beli 2: satu cadangan bila rusak saat demo. | S6: 2
A7: 3 | B7: A. Pengukuran & Kontrol | C7: Modul komunikasi RS485 | D7: MAX3485 TTL to RS485 module (3,3 V) | E7: Supply 3,3 V, terminal A/B, ada resistor terminasi 120 Ω | F7: 2 | G7: unit | H7: 33000 | I7: 93000 | J7: =IF(O7="Sudah punya",0,F7*H7) -> 66000 | K7: =IF(O7="Sudah punya",0,F7*I7) -> 186000 | L7: Wajib (1 cadangan) | M7: Tokopedia (dicek 2–4 Okt 2026) | N7: 136532 | O7: Diterima | P7: Tokopedia | Q7: Shopee | R7: JANGAN beli MAX485 biasa (5 V) — level 5 V bisa merusak pin RX ESP32. | S7: 2
A8: 4 | B8: A. Pengukuran & Kontrol | C8: Catu daya AC-DC 5 V | D8: Hi-Link HLK-5M05 | E8: Input 100–240 VAC, output 5 VDC 1 A (5 W), terisolasi | F8: 2 | G8: unit | H8: 39000 | I8: 58000 | J8: =IF(O8="Sudah punya",0,F8*H8) -> 78000 | K8: =IF(O8="Sudah punya",0,F8*I8) -> 116000 | L8: Wajib (1 cadangan) | M8: Tokopedia (dicek 2–4 Okt 2026) | N8: 58500 | O8: Diterima | P8: Tokopedia | Q8: Shopee | R8: Pilih 5M05 (5 W), bukan HLK-PM01 (3 W) — daya PM01 terlalu mepet untuk ESP32 + 3 relay. | S8: 2
B9: A. Pengukuran & Kontrol | C9: PSU 5V | N9: 30000 | O9: Diterima
A10: 5 | B10: A. Pengukuran & Kontrol | C10: Modul SSR 4 kanal (saklar step kapasitor) | D10: Modul SSR 4CH Omron G3MB-202P 5V, high-level trigger | E10: Zero-cross, beban 2 A 100–240 VAC per kanal, input 5 VDC | F10: 1 | G10: unit | H10: 80000 | I10: 90000 | J10: =IF(O10="Sudah punya",0,F10*H10) -> 80000 | K10: =IF(O10="Sudah punya",0,F10*I10) -> 90000 | L10: Wajib | M10: Tokopedia (dicek 2–4 Okt 2026) | N10: 60250 | O10: Diterima | P10: Tokopedia | Q10: Shopee | R10: Pilih 'HIGH level trigger' dan yang ada fuse per kanal. 3 kanal untuk 3 step, 1 kanal cadangan. | S10: 2
A11: 6 | B11: A. Pengukuran & Kontrol | C11: SSR satuan (cadangan) | D11: Omron G3MB-202P (DC5V) | E11: Zero-cross, 2 A 240 VAC, SIP-4 | F11: 2 | G11: pcs | H11: 15000 | I11: 20000 | J11: =IF(O11="Sudah punya",0,F11*H11) -> 30000 | K11: =IF(O11="Sudah punya",0,F11*I11) -> 40000 | L11: Cadangan | M11: Tokopedia (dicek 2–4 Okt 2026) | N11: 72000 | O11: Diterima | P11: Tokopedia | Q11: Shopee | R11: Pastikan kode -202P (zero-cross), BUKAN -202PL (tanpa zero-cross). | S11: 3
A12: 7 | B12: A. Pengukuran & Kontrol | C12: Modul relay 4 kanal (saklar beban demo) | D12: Modul relay 4CH 5V optocoupler (relay Songle SRD-05VDC) | E12: Kontak 10 A 250 VAC, optocoupler, jumper VCC–JD-VCC | F12: 1 | G12: unit | H12: 25000 | I12: 40000 | J12: =IF(O12="Sudah punya",0,F12*H12) -> 25000 | K12: =IF(O12="Sudah punya",0,F12*I12) -> 40000 | L12: Wajib | M12: Tokopedia (dicek 2–4 Okt 2026) | N12: 35500 | O12: Diterima | P12: Tokopedia | Q12: Shopee | R12: Harus ada jumper JD-VCC (agar VCC opto bisa 3,3 V dan koil 5 V). | S12: 2
A13: 8 | B13: A. Pengukuran & Kontrol | C13: Adaptor USB–RS485 (konfigurasi meter dari laptop) | D13: USB to RS485 converter CH340 | E13: Untuk setting baud rate DDSU666 & debug Modbus (QModMaster) | F13: 1 | G13: unit | H13: 15000 | I13: 30000 | J13: =IF(O13="Sudah punya",0,F13*H13) -> 15000 | K13: =IF(O13="Sudah punya",0,F13*I13) -> 30000 | L13: Disarankan | M13: Tokopedia (dicek 2–4 Okt 2026) | N13: 37000 | O13: Diterima | P13: Tokopedia | Q13: Shopee | R13: Sangat membantu saat uji meja: baca meter dari laptop sebelum firmware ESP32 siap. | S13: 1
A14: 9 | B14: A. Pengukuran & Kontrol | C14: Modul microSD (log data cadangan) | D14: Micro SD card module SPI (3,3 V / 5 V) | E14: Antarmuka SPI, level shifter onboard | F14: 1 | G14: unit | H14: 10000 | I14: 25000 | J14: =IF(O14="Sudah punya",0,F14*H14) -> 10000 | K14: =IF(O14="Sudah punya",0,F14*I14) -> 25000 | L14: Disarankan | M14: Tokopedia (dicek 2–4 Okt 2026) | N14: 7500 | O14: Diterima | P14: Tokopedia | Q14: Shopee | R14: Pin ESP32: SCK 18, MISO 19, MOSI 23, CS 5. | S14: 3
A15: 10 | B15: A. Pengukuran & Kontrol | C15: Kartu microSD | D15: microSD 8–16 GB Class 10 (SanDisk/V-Gen) | E15: Format FAT32 | F15: 1 | G15: pcs | H15: 40000 | I15: 70000 | J15: =IF(O15="Sudah punya",0,F15*H15) -> 0 | K15: =IF(O15="Sudah punya",0,F15*I15) -> 0 | L15: Disarankan | M15: Estimasi — cek saat beli | O15: Sudah punya | P15: Tokopedia | Q15: Shopee | R15: Format FAT32 sebelum dipakai. | S15: 3
A16: 11 | B16: B. Bank Kapasitor | C16: Kapasitor step (utama) | D16: CBB60 6 µF 450 VAC ±5%, model kabel | E16: Polypropylene film, 50/60 Hz; ±91 VAr per step pada 220 V | F16: 4 | G16: pcs | H16: 10000 | I16: 35000 | J16: =IF(O16="Sudah punya",0,F16*H16) -> 40000 | K16: =IF(O16="Sudah punya",0,F16*I16) -> 140000 | L16: Wajib (1 cadangan) | M16: Tokopedia (dicek 2–4 Okt 2026) | N16: 60000 | O16: Diterima | P16: Tokopedia | Q16: Shopee | R16: Harus CBB60/CBB65 tipe AC 450 V. JANGAN kapasitor elektrolit (ELCO) atau kapasitor start motor (CD60). | S16: 1
A17: 12 | B17: B. Bank Kapasitor | C17: Kapasitor penyesuai (setelah uji meja) | D17: CBB60 4 µF 450 VAC | E17: ±61 VAr per step pada 220 V | F17: 3 | G17: pcs | H17: 10000 | I17: 30000 | J17: =IF(O17="Sudah punya",0,F17*H17) -> 30000 | K17: =IF(O17="Sudah punya",0,F17*I17) -> 90000 | L17: Opsional | M17: Tokopedia (dicek 2–4 Okt 2026) | O17: Belum | P17: Tokopedia | Q17: Shopee | R17: Dipakai bila Q motor < ±250 VAr (hasil uji meja langkah 2). | S17: 2
A18: 13 | B18: B. Bank Kapasitor | C18: Kapasitor penyesuai (setelah uji meja) | D18: CBB60 8 µF 450 VAC | E18: ±122 VAr per step pada 220 V | F18: 3 | G18: pcs | H18: 10000 | I18: 35000 | J18: =IF(O18="Sudah punya",0,F18*H18) -> 30000 | K18: =IF(O18="Sudah punya",0,F18*I18) -> 105000 | L18: Opsional | M18: Tokopedia (dicek 2–4 Okt 2026) | O18: Belum | P18: Tokopedia | Q18: Shopee | R18: Dipakai bila Q motor > ±450 VAr. | S18: 2
A19: 14 | B19: B. Bank Kapasitor | C19: Resistor pelepas muatan | D19: Resistor metal film 100 kΩ 1 W | E19: 2 buah seri per kapasitor (200 kΩ, τ ≈ 1,2 s) | F19: 10 | G19: pcs | H19: 500 | I19: 1500 | J19: =IF(O19="Sudah punya",0,F19*H19) -> 5000 | K19: =IF(O19="Sudah punya",0,F19*I19) -> 15000 | L19: Wajib | M19: Estimasi — cek saat beli | N19: 10000 | O19: Diterima | P19: Tokopedia | Q19: Shopee | R19: Rating minimal 1 W. Dipasang paralel dengan setiap kapasitor. | S19: 1
A20: 15 | B20: B. Bank Kapasitor | C20: Fuse holder panel | D20: Fuse holder 5×20 mm (panel mount atau PCB) | E20: Rating 250 VAC 10 A | F20: 4 | G20: pcs | H20: 5000 | I20: 15000 | J20: =IF(O20="Sudah punya",0,F20*H20) -> 20000 | K20: =IF(O20="Sudah punya",0,F20*I20) -> 60000 | L20: Wajib | M20: Estimasi — cek saat beli | N20: 80000 | O20: Diterima | P20: Tokopedia | Q20: Shopee | R20: 3 untuk step kapasitor + 1 untuk input HLK-5M05. | S20: 1
A21: 16 | B21: B. Bank Kapasitor | C21: Sekring step kapasitor | D21: Fuse kaca 5×20 mm T1A 250V (slow-blow) | E21: Time-lag 1 A | F21: 10 | G21: pcs | H21: 1000 | I21: 3000 | J21: =IF(O21="Sudah punya",0,F21*H21) -> 10000 | K21: =IF(O21="Sudah punya",0,F21*I21) -> 30000 | L21: Wajib | M21: Estimasi — cek saat beli | N21: 40000 | O21: Diterima | P21: Tokopedia | Q21: Shopee | R21: Tipe T (slow-blow) agar tidak putus saat arus sambung kapasitor. | S21: 1
A22: 17 | B22: B. Bank Kapasitor | C22: Sekring catu daya | D22: Fuse kaca 5×20 mm 0,5 A 250V | E22: Proteksi input HLK-5M05 | F22: 5 | G22: pcs | H22: 1000 | I22: 3000 | J22: =IF(O22="Sudah punya",0,F22*H22) -> 5000 | K22: =IF(O22="Sudah punya",0,F22*I22) -> 15000 | L22: Wajib | M22: Estimasi — cek saat beli | O22: Diterima | P22: Tokopedia | Q22: Shopee | S22: 2
A23: 18 | B23: C. Beban Demo | C23: Motor induksi 1 fasa (beban induktif utama) | D23: Motor 1/4 HP (180 W) 4 pole, tipe kapasitor-start — mis. MAXPUMP YC712-4 / Yama 1/4 HP | E23: 220 V 50 Hz, 1400 rpm; dipasang tanpa beban mekanis | F23: 1 | G23: unit | H23: 890000 | I23: 1110000 | J23: =IF(O23="Sudah punya",0,F23*H23) -> 890000 | K23: =IF(O23="Sudah punya",0,F23*I23) -> 1110000 | L23: Wajib | M23: Tokopedia (dicek 2–4 Okt 2026) | O23: Belum | P23: Tokopedia | Q23: Shopee | R23: Utamakan kode 'YC' (kapasitor start). Hindari 'YL'/'YY' (ada kapasitor run → cos φ sudah tinggi, efek koreksi kurang terlihat). Tanyakan ke penjual. | S23: 1
A24: 19 | B24: C. Beban Demo | C24: Ballast magnetik (beban induktif tambahan) | D24: Philips BTA 36W 220V (ballast trafo TL magnetik) | E24: Untuk 1 lampu TL 36 W | F24: 1 | G24: pcs | H24: 90000 | I24: 110000 | J24: =IF(O24="Sudah punya",0,F24*H24) -> 90000 | K24: =IF(O24="Sudah punya",0,F24*I24) -> 110000 | L24: Disarankan | M24: Tokopedia (dicek 2–4 Okt 2026) | O24: Belum | P24: Tokopedia | Q24: Shopee | R24: Ballast MAGNETIK (trafo), bukan ballast elektronik. Wajib dipakai bersama lampu TL + starter. | S24: 3
A25: 20 | B25: C. Beban Demo | C25: Lampu TL set untuk ballast | D25: Tabung TL-D 36W + starter S10 + kap/fitting TL 1×36W | E25: Tanpa kapasitor kompensasi bawaan | F25: 1 | G25: set | H25: 50000 | I25: 100000 | J25: =IF(O25="Sudah punya",0,F25*H25) -> 50000 | K25: =IF(O25="Sudah punya",0,F25*I25) -> 100000 | L25: Disarankan | M25: Estimasi — cek saat beli | N25: 140000 | O25: Diterima | P25: Tokopedia | Q25: Shopee | R25: Bila kap bawaan punya kapasitor kompensasi, lepas kapasitornya agar beban tetap induktif. | S25: 3
A26: 21 | B26: C. Beban Demo | C26: Lampu halogen (beban resistif) | D26: Philips Halogen Plusline S 300W R7s 118 mm 230V | E26: Beban resistif murni ±300 W | F26: 1 | G26: pcs | H26: 35000 | I26: 75000 | J26: =IF(O26="Sudah punya",0,F26*H26) -> 35000 | K26: =IF(O26="Sudah punya",0,F26*I26) -> 75000 | L26: Wajib | M26: Estimasi — cek saat beli | O26: Belum | P26: Tokopedia | Q26: Shopee | R26: Panjang 118 mm, harus cocok dengan rumah lampu. | S26: 2
A27: 22 | B27: C. Beban Demo | C27: Rumah lampu sorot halogen | D27: Lampu sorot halogen R7s 118 mm (fixture 300–500 W) | E27: Rumah lampu + kaca pelindung | F27: 1 | G27: unit | H27: 40000 | I27: 100000 | J27: =IF(O27="Sudah punya",0,F27*H27) -> 40000 | K27: =IF(O27="Sudah punya",0,F27*I27) -> 100000 | L27: Wajib | M27: Estimasi — cek saat beli | O27: Belum | P27: Tokopedia | Q27: Shopee | R27: Lampu sangat panas — pasang di luar panel, beri jarak dari kabel. | S27: 2
A28: 23 | B28: C. Beban Demo | C28: Stopkontak beban elektronik AC–DC | D28: Stopkontak tempel/panel 1 lubang ber-arde | E28: 16 A 250 V | F28: 1 | G28: pcs | H28: 15000 | I28: 30000 | J28: =IF(O28="Sudah punya",0,F28*H28) -> 0 | K28: =IF(O28="Sudah punya",0,F28*I28) -> 0 | L28: Wajib | M28: Estimasi — cek saat beli | O28: Sudah punya | P28: Tokopedia | Q28: Shopee | R28: Untuk mencolok charger laptop (beban nonlinear) yang dikendalikan relay K3. | S28: 2
A29: 24 | B29: D. Proteksi & Panel | C29: Pengaman utama | D29: RCBO 1P+N 6 A 30 mA — mis. Chint NXBLE-32 / Schneider Domae DOMD01606 | E29: Proteksi arus lebih + arus bocor 30 mA | F29: 1 | G29: unit | H29: 76000 | I29: 200000 | J29: =IF(O29="Sudah punya",0,F29*H29) -> 76000 | K29: =IF(O29="Sudah punya",0,F29*I29) -> 200000 | L29: Wajib | M29: Tokopedia (dicek 2–4 Okt 2026) | N29: 110000 | O29: Diterima | P29: Tokopedia | Q29: Shopee | R29: Pilih 6 A dan 30 mA (bukan 300 mA). | S29: 1
A30: 25 | B30: D. Proteksi & Panel | C30: Tombol darurat | D30: Emergency stop push button 22 mm, merah, twist-release, kontak 1NC | E30: 10 A 250 VAC | F30: 1 | G30: pcs | H30: 25000 | I30: 60000 | J30: =IF(O30="Sudah punya",0,F30*H30) -> 25000 | K30: =IF(O30="Sudah punya",0,F30*I30) -> 60000 | L30: Wajib | M30: Estimasi — cek saat beli | N30: 20000 | O30: Diterima | P30: Tokopedia | Q30: Shopee | R30: Dipasang seri di jalur L setelah RCBO; penting untuk keselamatan saat demo di depan juri. | S30: 2
A31: 26 | B31: D. Proteksi & Panel | C31: Lampu indikator step & power | D31: Pilot lamp LED AD16-22DS 220 VAC 22 mm (3 hijau + 1 merah) | E31: Indikator step kapasitor ON dan panel bertegangan | F31: 4 | G31: pcs | H31: 8000 | I31: 15000 | J31: =IF(O31="Sudah punya",0,F31*H31) -> 32000 | K31: =IF(O31="Sudah punya",0,F31*I31) -> 60000 | L31: Disarankan | M31: Estimasi — cek saat beli | N31: 21000 | O31: Diterima | P31: Tokopedia | Q31: Shopee | R31: Hijau dipasang paralel setelah tiap SSR — juri melihat step mana yang aktif. | S31: 3
A32: 27 | B32: D. Proteksi & Panel | C32: Box panel | D32: Box panel indoor 30×40×20 cm, pintu akrilik, plat 1,2 mm | E32: Dengan mounting plate | F32: 1 | G32: unit | H32: 250000 | I32: 450000 | J32: =IF(O32="Sudah punya",0,F32*H32) -> 250000 | K32: =IF(O32="Sudah punya",0,F32*I32) -> 450000 | L32: Wajib | M32: Estimasi — cek saat beli | N32: 155000 | O32: Diterima | P32: Tokopedia | Q32: Shopee | R32: Pintu akrilik agar komponen terlihat juri tanpa membuka panel. | S32: 1
A33: 28 | B33: D. Proteksi & Panel | C33: Rel DIN | D33: Rel DIN 35 mm (top hat), 1 meter | E33: Untuk RCBO, meter, terminal | F33: 1 | G33: batang | H33: 15000 | I33: 30000 | J33: =IF(O33="Sudah punya",0,F33*H33) -> 15000 | K33: =IF(O33="Sudah punya",0,F33*I33) -> 30000 | L33: Wajib | M33: Estimasi — cek saat beli | N33: 18000 | O33: Diterima | P33: Tokopedia | Q33: Shopee | S33: 1
A34: 29 | B34: D. Proteksi & Panel | C34: Terminal block | D34: Terminal UK2.5B + end stopper + jumper bar | E34: 2,5 mm², 32 A; grup L, N, PE | F34: 20 | G34: pcs | H34: 2000 | I34: 5000 | J34: =IF(O34="Sudah punya",0,F34*H34) -> 40000 | K34: =IF(O34="Sudah punya",0,F34*I34) -> 100000 | L34: Wajib | M34: Estimasi — cek saat beli | N34: 35000 | O34: Diterima | P34: Tokopedia | Q34: Shopee | R34: Siapkan juga 2–4 end stopper. | S34: 1
A35: 30 | B35: D. Proteksi & Panel | C35: Kabel daya panel | D35: Kabel NYAF 1,5 mm² — merah (L), biru/hitam (N), kuning-hijau (PE) | E35: Serabut, 450/750 V | F35: 30 | G35: meter | H35: 3000 | I35: 5000 | J35: =IF(O35="Sudah punya",0,F35*H35) -> 90000 | K35: =IF(O35="Sudah punya",0,F35*I35) -> 150000 | L35: Wajib | M35: Estimasi — cek saat beli | N35: 0 | O35: Belum | P35: Tokopedia | Q35: Shopee | R35: ±10 m per warna. | S35: 1
A36: 31 | B36: D. Proteksi & Panel | C36: Kabel input + steker | D36: Kabel NYMHY 3×1,5 mm² 3 m + steker arde | E36: Dari stopkontak venue ke panel | F36: 1 | G36: set | H36: 40000 | I36: 80000 | J36: =IF(O36="Sudah punya",0,F36*H36) -> 40000 | K36: =IF(O36="Sudah punya",0,F36*I36) -> 80000 | L36: Wajib | M36: Estimasi — cek saat beli | N36: 0 | O36: Belum | P36: Tokopedia | Q36: Shopee | S36: 1
A37: 32 | B37: D. Proteksi & Panel | C37: Aksesoris pengawatan | D37: Skun/ferrule pin + heat shrink + cable tie + duct kabel | E37: Paket campuran | F37: 1 | G37: paket | H37: 50000 | I37: 100000 | J37: =IF(O37="Sudah punya",0,F37*H37) -> 50000 | K37: =IF(O37="Sudah punya",0,F37*I37) -> 100000 | L37: Wajib | M37: Estimasi — cek saat beli | O37: Belum | P37: Tokopedia | Q37: Shopee | S37: 2
A38: 33 | B38: D. Proteksi & Panel | C38: Aksesoris elektronik | D38: Kabel jumper dupont, PCB lubang, spacer & baut M3 | E38: Untuk zona tegangan rendah | F38: 1 | G38: paket | H38: 40000 | I38: 70000 | J38: =IF(O38="Sudah punya",0,F38*H38) -> 40000 | K38: =IF(O38="Sudah punya",0,F38*I38) -> 70000 | L38: Wajib | M38: Estimasi — cek saat beli | O38: Belum | P38: Tokopedia | Q38: Shopee | S38: 2
A39: 34 | B39: D. Proteksi & Panel | C39: Kabel RS485 | D39: Kabel UTP Cat5e (pakai 1 pasang twisted), 2 m | E39: Meter ↔ MAX3485 | F39: 1 | G39: pcs | H39: 10000 | I39: 20000 | J39: =IF(O39="Sudah punya",0,F39*H39) -> 0 | K39: =IF(O39="Sudah punya",0,F39*I39) -> 0 | L39: Wajib | M39: Estimasi — cek saat beli | O39: Sudah punya | P39: Tokopedia | Q39: Shopee | R39: Ada di lemari CAT5E | S39: 2
A40: 35 | B40: E. Alat Ukur & Perkakas | C40: Tang ampere (bukti fisik di demo) | D40: UNI-T UT204+ True RMS AC/DC clamp meter | E40: 600 A AC/DC, ukur V, Ω | F40: 1 | G40: unit | H40: 450000 | I40: 700000 | J40: =IF(O40="Sudah punya",0,F40*H40) -> 450000 | K40: =IF(O40="Sudah punya",0,F40*I40) -> 700000 | L40: Disarankan | M40: Estimasi — cek saat beli | O40: Belum | P40: Tokopedia | Q40: Shopee | R40: Dijepit di kabel L sebelum kapasitor: juri melihat arus turun saat step masuk. Lewati bila sudah punya. | S40: 3
...

Sheet Tahap 1
A1: TAHAP 1 — Uji meja & barang yang lama dikirim
A2: Kapan dipesan: | C2: Pesan hari ini, Senin 5 Okt 2026 (target tiba 7–8 Okt).
A3: Tujuan: | C3: Membuktikan Q turun saat kapasitor masuk (uji meja tanpa ESP32) dan menentukan nilai µF final.
A4: Qty, harga, dan Status diubah di sheet 'Daftar Belanja'; sheet ini ikut berubah otomatis.
A6: No | B6: No di Daftar Belanja | C6: Komponen | D6: Merek / Model / Kode seri | E6: Qty | F6: Satuan | G6: Harga satuan min (Rp) | H6: Harga satuan maks (Rp) | I6: Subtotal min (Rp) | J6: Subtotal maks (Rp) | K6: Harga Beli (Rp) | L6: Status | M6: Link Tokopedia | N6: Link Shopee | O6: Alasan dibeli di tahap ini | P6: Catatan agar tidak salah beli
A7: 1 | B7: 1 | C7: ='Daftar Belanja'!C5 -> Meter energi 1 fasa (Modbus) | D7: ='Daftar Belanja'!D5 -> CHINT DDSU666 — varian RS485 Modbus, 5(80)A, 230V 1P2W | E7: ='Daftar Belanja'!F5 -> 1 | F7: ='Daftar Belanja'!G5 -> unit | G7: ='Daftar Belanja'!H5 -> 720000 | H7: ='Daftar Belanja'!I5 -> 800000 | I7: ='Daftar Belanja'!J5 -> 720000 | J7: ='Daftar Belanja'!K5 -> 800000 | K7: ='Daftar Belanja'!N5 -> 329999 | L7: ='Daftar Belanja'!O5 -> Diterima | M7: Tokopedia | N7: Shopee | O7: Inti pengukuran; dibutuhkan untuk uji meja. Stok terbatas, harga paling tinggi. | P7: =IF('Daftar Belanja'!R5="","",'Daftar Belanja'!R5) -> WAJIB ada tulisan 'RS485' di judul. Versi tanpa RS485 (±Rp410 rb) TIDAK bisa dibaca ESP32. Minta penjual foto terminal 24/25 (A/B).
A8: 2 | B8: 8 | C8: ='Daftar Belanja'!C13 -> Adaptor USB–RS485 (konfigurasi meter dari laptop) | D8: ='Daftar Belanja'!D13 -> USB to RS485 converter CH340 | E8: ='Daftar Belanja'!F13 -> 1 | F8: ='Daftar Belanja'!G13 -> unit | G8: ='Daftar Belanja'!H13 -> 15000 | H8: ='Daftar Belanja'!I13 -> 30000 | I8: ='Daftar Belanja'!J13 -> 15000 | J8: ='Daftar Belanja'!K13 -> 30000 | K8: ='Daftar Belanja'!N13 -> 37000 | L8: ='Daftar Belanja'!O13 -> Diterima | M8: Tokopedia | N8: Shopee | O8: Membaca meter langsung dari laptop saat uji meja, sebelum firmware ESP32 siap. | P8: =IF('Daftar Belanja'!R13="","",'Daftar Belanja'!R13) -> Sangat membantu saat uji meja: baca meter dari laptop sebelum firmware ESP32 siap.
A9: 3 | B9: 11 | C9: ='Daftar Belanja'!C16 -> Kapasitor step (utama) | D9: ='Daftar Belanja'!D16 -> CBB60 6 µF 450 VAC ±5%, model kabel | E9: ='Daftar Belanja'!F16 -> 4 | F9: ='Daftar Belanja'!G16 -> pcs | G9: ='Daftar Belanja'!H16 -> 10000 | H9: ='Daftar Belanja'!I16 -> 35000 | I9: ='Daftar Belanja'!J16 -> 40000 | J9: ='Daftar Belanja'!K16 -> 140000 | K9: ='Daftar Belanja'!N16 -> 60000 | L9: ='Daftar Belanja'!O16 -> Diterima | M9: Tokopedia | N9: Shopee | O9: Uji meja langkah 1 & 3 (kapasitor saja, lalu motor + 1/2/3 kapasitor). | P9: =IF('Daftar Belanja'!R16="","",'Daftar Belanja'!R16) -> Harus CBB60/CBB65 tipe AC 450 V. JANGAN kapasitor elektrolit (ELCO) atau kapasitor start motor (CD60).
A10: 4 | B10: 14 | C10: ='Daftar Belanja'!C19 -> Resistor pelepas muatan | D10: ='Daftar Belanja'!D19 -> Resistor metal film 100 kΩ 1 W | E10: ='Daftar Belanja'!F19 -> 10 | F10: ='Daftar Belanja'!G19 -> pcs | G10: ='Daftar Belanja'!H19 -> 500 | H10: ='Daftar Belanja'!I19 -> 1500 | I10: ='Daftar Belanja'!J19 -> 5000 | J10: ='Daftar Belanja'!K19 -> 15000 | K10: ='Daftar Belanja'!N19 -> 10000 | L10: ='Daftar Belanja'!O19 -> Diterima | M10: Tokopedia | N10: Shopee | O10: Keselamatan: kapasitor wajib punya pelepas muatan sejak uji pertama. | P10: =IF('Daftar Belanja'!R19="","",'Daftar Belanja'!R19) -> Rating minimal 1 W. Dipasang paralel dengan setiap kapasitor.
A11: 5 | B11: 15 | C11: ='Daftar Belanja'!C20 -> Fuse holder panel | D11: ='Daftar Belanja'!D20 -> Fuse holder 5×20 mm (panel mount atau PCB) | E11: ='Daftar Belanja'!F20 -> 4 | F11: ='Daftar Belanja'!G20 -> pcs | G11: ='Daftar Belanja'!H20 -> 5000 | H11: ='Daftar Belanja'!I20 -> 15000 | I11: ='Daftar Belanja'!J20 -> 20000 | J11: ='Daftar Belanja'!K20 -> 60000 | K11: ='Daftar Belanja'!N20 -> 80000 | L11: ='Daftar Belanja'!O20 -> Diterima | M11: Tokopedia | N11: Shopee | O11: Proteksi tiap step kapasitor sejak uji meja. | P11: =IF('Daftar Belanja'!R20="","",'Daftar Belanja'!R20) -> 3 untuk step kapasitor + 1 untuk input HLK-5M05.
A12: 6 | B12: 16 | C12: ='Daftar Belanja'!C21 -> Sekring step kapasitor | D12: ='Daftar Belanja'!D21 -> Fuse kaca 5×20 mm T1A 250V (slow-blow) | E12: ='Daftar Belanja'!F21 -> 10 | F12: ='Daftar Belanja'!G21 -> pcs | G12: ='Daftar Belanja'!H21 -> 1000 | H12: ='Daftar Belanja'!I21 -> 3000 | I12: ='Daftar Belanja'!J21 -> 10000 | J12: ='Daftar Belanja'!K21 -> 30000 | K12: ='Daftar Belanja'!N21 -> 40000 | L12: ='Daftar Belanja'!O21 -> Diterima | M12: Tokopedia | N12: Shopee | O12: Sekring untuk fuse holder step kapasitor. | P12: =IF('Daftar Belanja'!R21="","",'Daftar Belanja'!R21) -> Tipe T (slow-blow) agar tidak putus saat arus sambung kapasitor.
A13: 7 | B13: 18 | C13: ='Daftar Belanja'!C23 -> Motor induksi 1 fasa (beban induktif utama) | D13: ='Daftar Belanja'!D23 -> Motor 1/4 HP (180 W) 4 pole, tipe kapasitor-start — mis. MAXPUMP YC712-4 / Yama 1/4 HP | E13: ='Daftar Belanja'!F23 -> 1 | F13: ='Daftar Belanja'!G23 -> unit | G13: ='Daftar Belanja'!H23 -> 890000 | H13: ='Daftar Belanja'!I23 -> 1110000 | I13: ='Daftar Belanja'!J23 -> 890000 | J13: ='Daftar Belanja'!K23 -> 1110000 | K13: ='Daftar Belanja'!N23 -> 0 | L13: ='Daftar Belanja'!O23 -> Belum | M13: Tokopedia | N13: Shopee | O13: Beban induktif utama; Q motor menentukan nilai µF final. Barang berat, pengiriman lama. | P13: =IF('Daftar Belanja'!R23="","",'Daftar Belanja'!R23) -> Utamakan kode 'YC' (kapasitor start). Hindari 'YL'/'YY' (ada kapasitor run → cos φ sudah tinggi, efek koreksi kurang terlihat). Tanyakan ke penjual.
A14: 8 | B14: 24 | C14: ='Daftar Belanja'!C29 -> Pengaman utama | D14: ='Daftar Belanja'!D29 -> RCBO 1P+N 6 A 30 mA — mis. Chint NXBLE-32 / Schneider Domae DOMD01606 | E14: ='Daftar Belanja'!F29 -> 1 | F14: ='Daftar Belanja'!G29 -> unit | G14: ='Daftar Belanja'!H29 -> 76000 | H14: ='Daftar Belanja'!I29 -> 200000 | I14: ='Daftar Belanja'!J29 -> 76000 | J14: ='Daftar Belanja'!K29 -> 200000 | K14: ='Daftar Belanja'!N29 -> 110000 | L14: ='Daftar Belanja'!O29 -> Diterima | M14: Tokopedia | N14: Shopee | O14: Keselamatan saat uji meja 220 V. | P14: =IF('Daftar Belanja'!R29="","",'Daftar Belanja'!R29) -> Pilih 6 A dan 30 mA (bukan 300 mA).
A15: 9 | B15: 27 | C15: ='Daftar Belanja'!C32 -> Box panel | D15: ='Daftar Belanja'!D32 -> Box panel indoor 30×40×20 cm, pintu akrilik, plat 1,2 mm | E15: ='Daftar Belanja'!F32 -> 1 | F15: ='Daftar Belanja'!G32 -> unit | G15: ='Daftar Belanja'!H32 -> 250000 | H15: ='Daftar Belanja'!I32 -> 450000 | I15: ='Daftar Belanja'!J32 -> 250000 | J15: ='Daftar Belanja'!K32 -> 450000 | K15: ='Daftar Belanja'!N32 -> 155000 | L15: ='Daftar Belanja'!O32 -> Diterima | M15: Tokopedia | N15: Shopee | O15: Pengiriman paling lama (custom pintu akrilik); bisa dipakai sebagai papan uji. | P15: =IF('Daftar Belanja'!R32="","",'Daftar Belanja'!R32) -> Pintu akrilik agar komponen terlihat juri tanpa membuka panel.
A16: 10 | B16: 28 | C16: ='Daftar Belanja'!C33 -> Rel DIN | D16: ='Daftar Belanja'!D33 -> Rel DIN 35 mm (top hat), 1 meter | E16: ='Daftar Belanja'!F33 -> 1 | F16: ='Daftar Belanja'!G33 -> batang | G16: ='Daftar Belanja'!H33 -> 15000 | H16: ='Daftar Belanja'!I33 -> 30000 | I16: ='Daftar Belanja'!J33 -> 15000 | J16: ='Daftar Belanja'!K33 -> 30000 | K16: ='Daftar Belanja'!N33 -> 18000 | L16: ='Daftar Belanja'!O33 -> Diterima | M16: Tokopedia | N16: Shopee | O16: Dudukan RCBO, meter, dan terminal. | P16: =IF('Daftar Belanja'!R33="","",'Daftar Belanja'!R33)
A17: 11 | B17: 29 | C17: ='Daftar Belanja'!C34 -> Terminal block | D17: ='Daftar Belanja'!D34 -> Terminal UK2.5B + end stopper + jumper bar | E17: ='Daftar Belanja'!F34 -> 20 | F17: ='Daftar Belanja'!G34 -> pcs | G17: ='Daftar Belanja'!H34 -> 2000 | H17: ='Daftar Belanja'!I34 -> 5000 | I17: ='Daftar Belanja'!J34 -> 40000 | J17: ='Daftar Belanja'!K34 -> 100000 | K17: ='Daftar Belanja'!N34 -> 35000 | L17: ='Daftar Belanja'!O34 -> Diterima | M17: Tokopedia | N17: Shopee | O17: Sambungan L, N, PE untuk rangkaian uji meja. | P17: =IF('Daftar Belanja'!R34="","",'Daftar Belanja'!R34) -> Siapkan juga 2–4 end stopper.
A18: 12 | B18: 30 | C18: ='Daftar Belanja'!C35 -> Kabel daya panel | D18: ='Daftar Belanja'!D35 -> Kabel NYAF 1,5 mm² — merah (L), biru/hitam (N), kuning-hijau (PE) | E18: ='Daftar Belanja'!F35 -> 30 | F18: ='Daftar Belanja'!G35 -> meter | G18: ='Daftar Belanja'!H35 -> 3000 | H18: ='Daftar Belanja'!I35 -> 5000 | I18: ='Daftar Belanja'!J35 -> 90000 | J18: ='Daftar Belanja'!K35 -> 150000 | K18: ='Daftar Belanja'!N35 -> 0 | L18: ='Daftar Belanja'!O35 -> Belum | M18: Tokopedia | N18: Shopee | O18: Pengawatan rangkaian daya. | P18: =IF('Daftar Belanja'!R35="","",'Daftar Belanja'!R35) -> ±10 m per warna.
A19: 13 | B19: 31 | C19: ='Daftar Belanja'!C36 -> Kabel input + steker | D19: ='Daftar Belanja'!D36 -> Kabel NYMHY 3×1,5 mm² 3 m + steker arde | E19: ='Daftar Belanja'!F36 -> 1 | F19: ='Daftar Belanja'!G36 -> set | G19: ='Daftar Belanja'!H36 -> 40000 | H19: ='Daftar Belanja'!I36 -> 80000 | I19: ='Daftar Belanja'!J36 -> 40000 | J19: ='Daftar Belanja'!K36 -> 80000 | K19: ='Daftar Belanja'!N36 -> 0 | L19: ='Daftar Belanja'!O36 -> Belum | M19: Tokopedia | N19: Shopee | O19: Sumber listrik dari stopkontak ke rangkaian. | P19: =IF('Daftar Belanja'!R36="","",'Daftar Belanja'!R36)
A20: 14 | B20: 36 | C20: ='Daftar Belanja'!C41 -> Multimeter digital | D20: ='Daftar Belanja'!D41 -> UNI-T UT33D+ atau setara | E20: ='Daftar Belanja'!F41 -> 1 | F20: ='Daftar Belanja'!G41 -> unit | G20: ='Daftar Belanja'!H41 -> 100000 | H20: ='Daftar Belanja'!I41 -> 250000 | I20: ='Daftar Belanja'!J41 -> 0 | J20: ='Daftar Belanja'!K41 -> 0 | K20: ='Daftar Belanja'!N41 -> 0 | L20: ='Daftar Belanja'!O41 -> Sudah punya | M20: Tokopedia | N20: Shopee | O20: Cek kontinuitas dan tegangan sisa kapasitor sebelum menyentuh rangkaian. Lewati bila sudah punya. | P20: =IF('Daftar Belanja'!R41="","",'Daftar Belanja'!R41) -> Lewati bila sudah punya.
C21: TOTAL TAHAP 1 | I21: =SUM(I7:I20) -> 2211000 | J21: =SUM(J7:J20) -> 3195000 | K21: =SUM(K7:K20) -> 874999
C22: Item sudah diterima / sudah punya | I22: =COUNTIF(L7:L20,"Diterima")+COUNTIF(L7:L20,"Sudah punya")&" dari "&COUNTA(C7:C20)&" item" -> 11 dari 14 item
A24: Tahap 1 dianggap selesai bila:
A25: ☐ | C25: Meter terbaca dari laptop lewat USB–RS485 (V ≈ 220 V, f ≈ 50 Hz).
A26: ☐ | C26: 1 kapasitor saja → Q ≈ −91 VAr, I ≈ 0,41 A.
A27: ☐ | C27: Motor saja → P, Q, cos φ tercatat.
A28: ☐ | C28: Motor + 1/2/3 kapasitor → Q turun bertahap, cos φ naik.
A29: ☐ | C29: Nilai µF final diputuskan (6 µF tetap, atau ganti 4/8 µF di Tahap 2).

Sheet Tahap 2
A1: TAHAP 2 — Kontrol otomatis & perakitan panel
A2: Kapan dipesan: | C2: Pesan Kamis–Jumat, 8–9 Okt 2026, setelah uji meja Tahap 1.
A3: Tujuan: | C3: ESP32 membaca DDSU666, mengendalikan step kapasitor dan beban secara otomatis, data tampil di dashboard MQTT.
A4: Qty, harga, dan Status diubah di sheet 'Daftar Belanja'; sheet ini ikut berubah otomatis.
A6: No | B6: No di Daftar Belanja | C6: Komponen | D6: Merek / Model / Kode seri | E6: Qty | F6: Satuan | G6: Harga satuan min (Rp) | H6: Harga satuan maks (Rp) | I6: Subtotal min (Rp) | J6: Subtotal maks (Rp) | K6: Harga Beli (RP) | L6: Status | M6: Link Tokopedia | N6: Link Shopee | O6: Alasan dibeli di tahap ini | P6: Catatan agar tidak salah beli
A7: 1 | B7: 2 | C7: ='Daftar Belanja'!C6 -> Mikrokontroler / edge controller | D7: ='Daftar Belanja'!D6 -> ESP32 DevKit V1 — modul ESP-WROOM-32, 30 pin, USB-C | E7: ='Daftar Belanja'!F6 -> 2 | F7: ='Daftar Belanja'!G6 -> unit | G7: ='Daftar Belanja'!H6 -> 65000 | H7: ='Daftar Belanja'!I6 -> 100000 | I7: ='Daftar Belanja'!J6 -> 0 | J7: ='Daftar Belanja'!K6 -> 0 | K7: ='Daftar Belanja'!N6 -> 0 | L7: ='Daftar Belanja'!O6 -> Sudah punya | M7: Tokopedia | N7: Shopee | O7: Edge controller untuk mengotomatiskan uji meja. | P7: =IF('Daftar Belanja'!R6="","",'Daftar Belanja'!R6) -> Pilih WROOM-32 (bukan WROVER — GPIO16/17 dipakai PSRAM). Beli 2: satu cadangan bila rusak saat demo.
A8: 2 | B8: 3 | C8: ='Daftar Belanja'!C7 -> Modul komunikasi RS485 | D8: ='Daftar Belanja'!D7 -> MAX3485 TTL to RS485 module (3,3 V) | E8: ='Daftar Belanja'!F7 -> 2 | F8: ='Daftar Belanja'!G7 -> unit | G8: ='Daftar Belanja'!H7 -> 33000 | H8: ='Daftar Belanja'!I7 -> 93000 | I8: ='Daftar Belanja'!J7 -> 66000 | J8: ='Daftar Belanja'!K7 -> 186000 | K8: ='Daftar Belanja'!N7 -> 136532 | L8: ='Daftar Belanja'!O7 -> Diterima | M8: Tokopedia | N8: Shopee | O8: Penghubung meter ↔ ESP32. | P8: =IF('Daftar Belanja'!R7="","",'Daftar Belanja'!R7) -> JANGAN beli MAX485 biasa (5 V) — level 5 V bisa merusak pin RX ESP32.
A9: 3 | B9: 4 | C9: ='Daftar Belanja'!C8 -> Catu daya AC-DC 5 V | D9: ='Daftar Belanja'!D8 -> Hi-Link HLK-5M05 | E9: ='Daftar Belanja'!F8 -> 2 | F9: ='Daftar Belanja'!G8 -> unit | G9: ='Daftar Belanja'!H8 -> 39000 | H9: ='Daftar Belanja'!I8 -> 58000 | I9: ='Daftar Belanja'!J8 -> 78000 | J9: ='Daftar Belanja'!K8 -> 116000 | K9: ='Daftar Belanja'!N8 -> 58500 | L9: ='Daftar Belanja'!O8 -> Diterima | M9: Tokopedia | N9: Shopee | O9: Catu 5 V untuk ESP32, SSR, dan relay. | P9: =IF('Daftar Belanja'!R8="","",'Daftar Belanja'!R8) -> Pilih 5M05 (5 W), bukan HLK-PM01 (3 W) — daya PM01 terlalu mepet untuk ESP32 + 3 relay.
A10: 4 | B10: 5 | C10: ='Daftar Belanja'!C10 -> Modul SSR 4 kanal (saklar step kapasitor) | D10: ='Daftar Belanja'!D10 -> Modul SSR 4CH Omron G3MB-202P 5V, high-level trigger | E10: ='Daftar Belanja'!F10 -> 1 | F10: ='Daftar Belanja'!G10 -> unit | G10: ='Daftar Belanja'!H10 -> 80000 | H10: ='Daftar Belanja'!I10 -> 90000 | I10: ='Daftar Belanja'!J10 -> 80000 | J10: ='Daftar Belanja'!K10 -> 90000 | K10: ='Daftar Belanja'!N10 -> 60250 | L10: ='Daftar Belanja'!O10 -> Diterima | M10: Tokopedia | N10: Shopee | O10: Saklar otomatis 3 step kapasitor. | P10: =IF('Daftar Belanja'!R10="","",'Daftar Belanja'!R10) -> Pilih 'HIGH level trigger' dan yang ada fuse per kanal. 3 kanal untuk 3 step, 1 kanal cadangan.
A11: 5 | B11: 7 | C11: ='Daftar Belanja'!C12 -> Modul relay 4 kanal (saklar beban demo) | D11: ='Daftar Belanja'!D12 -> Modul relay 4CH 5V optocoupler (relay Songle SRD-05VDC) | E11: ='Daftar Belanja'!F12 -> 1 | F11: ='Daftar Belanja'!G12 -> unit | G11: ='Daftar Belanja'!H12 -> 25000 | H11: ='Daftar Belanja'!I12 -> 40000 | I11: ='Daftar Belanja'!J12 -> 25000 | J11: ='Daftar Belanja'!K12 -> 40000 | K11: ='Daftar Belanja'!N12 -> 35500 | L11: ='Daftar Belanja'!O12 -> Diterima | M11: Tokopedia | N11: Shopee | O11: Saklar beban demo (motor, lampu, beban AC–DC) sesuai profil beban. | P11: =IF('Daftar Belanja'!R12="","",'Daftar Belanja'!R12) -> Harus ada jumper JD-VCC (agar VCC opto bisa 3,3 V dan koil 5 V).
A12: 6 | B12: 12 | C12: ='Daftar Belanja'!C17 -> Kapasitor penyesuai (setelah uji meja) | D12: ='Daftar Belanja'!D17 -> CBB60 4 µF 450 VAC | E12: ='Daftar Belanja'!F17 -> 3 | F12: ='Daftar Belanja'!G17 -> pcs | G12: ='Daftar Belanja'!H17 -> 10000 | H12: ='Daftar Belanja'!I17 -> 30000 | I12: ='Daftar Belanja'!J17 -> 30000 | J12: ='Daftar Belanja'!K17 -> 90000 | K12: ='Daftar Belanja'!N17 -> 0 | L12: ='Daftar Belanja'!O17 -> Belum | M12: Tokopedia | N12: Shopee | O12: BELI HANYA JIKA uji meja menunjukkan Q motor < ±250 VAr. | P12: =IF('Daftar Belanja'!R17="","",'Daftar Belanja'!R17) -> Dipakai bila Q motor < ±250 VAr (hasil uji meja langkah 2).
A13: 7 | B13: 13 | C13: ='Daftar Belanja'!C18 -> Kapasitor penyesuai (setelah uji meja) | D13: ='Daftar Belanja'!D18 -> CBB60 8 µF 450 VAC | E13: ='Daftar Belanja'!F18 -> 3 | F13: ='Daftar Belanja'!G18 -> pcs | G13: ='Daftar Belanja'!H18 -> 10000 | H13: ='Daftar Belanja'!I18 -> 35000 | I13: ='Daftar Belanja'!J18 -> 30000 | J13: ='Daftar Belanja'!K18 -> 105000 | K13: ='Daftar Belanja'!N18 -> 0 | L13: ='Daftar Belanja'!O18 -> Belum | M13: Tokopedia | N13: Shopee | O13: BELI HANYA JIKA uji meja menunjukkan Q motor > ±450 VAr. | P13: =IF('Daftar Belanja'!R18="","",'Daftar Belanja'!R18) -> Dipakai bila Q motor > ±450 VAr.
A14: 8 | B14: 17 | C14: ='Daftar Belanja'!C22 -> Sekring catu daya | D14: ='Daftar Belanja'!D22 -> Fuse kaca 5×20 mm 0,5 A 250V | E14: ='Daftar Belanja'!F22 -> 5 | F14: ='Daftar Belanja'!G22 -> pcs | G14: ='Daftar Belanja'!H22 -> 1000 | H14: ='Daftar Belanja'!I22 -> 3000 | I14: ='Daftar Belanja'!J22 -> 5000 | J14: ='Daftar Belanja'!K22 -> 15000 | K14: ='Daftar Belanja'!N22 -> 0 | L14: ='Daftar Belanja'!O22 -> Diterima | M14: Tokopedia | N14: Shopee | O14: Proteksi input HLK-5M05. | P14: =IF('Daftar Belanja'!R22="","",'Daftar Belanja'!R22)
A15: 9 | B15: 21 | C15: ='Daftar Belanja'!C26 -> Lampu halogen (beban resistif) | D15: ='Daftar Belanja'!D26 -> Philips Halogen Plusline S 300W R7s 118 mm 230V | E15: ='Daftar Belanja'!F26 -> 1 | F15: ='Daftar Belanja'!G26 -> pcs | G15: ='Daftar Belanja'!H26 -> 35000 | H15: ='Daftar Belanja'!I26 -> 75000 | I15: ='Daftar Belanja'!J26 -> 35000 | J15: ='Daftar Belanja'!K26 -> 75000 | K15: ='Daftar Belanja'!N26 -> 0 | L15: ='Daftar Belanja'!O26 -> Belum | M15: Tokopedia | N15: Shopee | O15: Beban resistif untuk profil beban 12 menit. | P15: =IF('Daftar Belanja'!R26="","",'Daftar Belanja'!R26) -> Panjang 118 mm, harus cocok dengan rumah lampu.
A16: 10 | B16: 22 | C16: ='Daftar Belanja'!C27 -> Rumah lampu sorot halogen | D16: ='Daftar Belanja'!D27 -> Lampu sorot halogen R7s 118 mm (fixture 300–500 W) | E16: ='Daftar Belanja'!F27 -> 1 | F16: ='Daftar Belanja'!G27 -> unit | G16: ='Daftar Belanja'!H27 -> 40000 | H16: ='Daftar Belanja'!I27 -> 100000 | I16: ='Daftar Belanja'!J27 -> 40000 | J16: ='Daftar Belanja'!K27 -> 100000 | K16: ='Daftar Belanja'!N27 -> 0 | L16: ='Daftar Belanja'!O27 -> Belum | M16: Tokopedia | N16: Shopee | O16: Rumah lampu untuk halogen 300 W. | P16: =IF('Daftar Belanja'!R27="","",'Daftar Belanja'!R27) -> Lampu sangat panas — pasang di luar panel, beri jarak dari kabel.
A17: 11 | B17: 23 | C17: ='Daftar Belanja'!C28 -> Stopkontak beban elektronik AC–DC | D17: ='Daftar Belanja'!D28 -> Stopkontak tempel/panel 1 lubang ber-arde | E17: ='Daftar Belanja'!F28 -> 1 | F17: ='Daftar Belanja'!G28 -> pcs | G17: ='Daftar Belanja'!H28 -> 15000 | H17: ='Daftar Belanja'!I28 -> 30000 | I17: ='Daftar Belanja'!J28 -> 0 | J17: ='Daftar Belanja'!K28 -> 0 | K17: ='Daftar Belanja'!N28 -> 0 | L17: ='Daftar Belanja'!O28 -> Sudah punya | M17: Tokopedia | N17: Shopee | O17: Colokan beban elektronik AC–DC (charger laptop). | P17: =IF('Daftar Belanja'!R28="","",'Daftar Belanja'!R28) -> Untuk mencolok charger laptop (beban nonlinear) yang dikendalikan relay K3.
A18: 12 | B18: 25 | C18: ='Daftar Belanja'!C30 -> Tombol darurat | D18: ='Daftar Belanja'!D30 -> Emergency stop push button 22 mm, merah, twist-release, kontak 1NC | E18: ='Daftar Belanja'!F30 -> 1 | F18: ='Daftar Belanja'!G30 -> pcs | G18: ='Daftar Belanja'!H30 -> 25000 | H18: ='Daftar Belanja'!I30 -> 60000 | I18: ='Daftar Belanja'!J30 -> 25000 | J18: ='Daftar Belanja'!K30 -> 60000 | K18: ='Daftar Belanja'!N30 -> 20000 | L18: ='Daftar Belanja'!O30 -> Diterima | M18: Tokopedia | N18: Shopee | O18: Dipasang saat perakitan panel final (keselamatan demo). | P18: =IF('Daftar Belanja'!R30="","",'Daftar Belanja'!R30) -> Dipasang seri di jalur L setelah RCBO; penting untuk keselamatan saat demo di depan juri.
A19: 13 | B19: 32 | C19: ='Daftar Belanja'!C37 -> Aksesoris pengawatan | D19: ='Daftar Belanja'!D37 -> Skun/ferrule pin + heat shrink + cable tie + duct kabel | E19: ='Daftar Belanja'!F37 -> 1 | F19: ='Daftar Belanja'!G37 -> paket | G19: ='Daftar Belanja'!H37 -> 50000 | H19: ='Daftar Belanja'!I37 -> 100000 | I19: ='Daftar Belanja'!J37 -> 50000 | J19: ='Daftar Belanja'!K37 -> 100000 | K19: ='Daftar Belanja'!N37 -> 0 | L19: ='Daftar Belanja'!O37 -> Belum | M19: Tokopedia | N19: Shopee | O19: Merapikan pengawatan panel. | P19: =IF('Daftar Belanja'!R37="","",'Daftar Belanja'!R37)
A20: 14 | B20: 33 | C20: ='Daftar Belanja'!C38 -> Aksesoris elektronik | D20: ='Daftar Belanja'!D38 -> Kabel jumper dupont, PCB lubang, spacer & baut M3 | E20: ='Daftar Belanja'!F38 -> 1 | F20: ='Daftar Belanja'!G38 -> paket | G20: ='Daftar Belanja'!H38 -> 40000 | H20: ='Daftar Belanja'!I38 -> 70000 | I20: ='Daftar Belanja'!J38 -> 40000 | J20: ='Daftar Belanja'!K38 -> 70000 | K20: ='Daftar Belanja'!N38 -> 0 | L20: ='Daftar Belanja'!O38 -> Belum | M20: Tokopedia | N20: Shopee | O20: Perakitan zona tegangan rendah. | P20: =IF('Daftar Belanja'!R38="","",'Daftar Belanja'!R38)
A21: 15 | B21: 34 | C21: ='Daftar Belanja'!C39 -> Kabel RS485 | D21: ='Daftar Belanja'!D39 -> Kabel UTP Cat5e (pakai 1 pasang twisted), 2 m | E21: ='Daftar Belanja'!F39 -> 1 | F21: ='Daftar Belanja'!G39 -> pcs | G21: ='Daftar Belanja'!H39 -> 10000 | H21: ='Daftar Belanja'!I39 -> 20000 | I21: ='Daftar Belanja'!J39 -> 0 | J21: ='Daftar Belanja'!K39 -> 0 | K21: ='Daftar Belanja'!N39 -> 0 | L21: ='Daftar Belanja'!O39 -> Sudah punya | M21: Tokopedia | N21: Shopee | O21: Jalur RS485 meter ↔ MAX3485. | P21: =IF('Daftar Belanja'!R39="","",'Daftar Belanja'!R39) -> Ada di lemari CAT5E
C22: TOTAL TAHAP 2 | I22: =SUM(I7:I21) -> 504000 | J22: =SUM(J7:J21) -> 1047000 | K22: =SUM(K7:K21) -> 310782
C23: Item sudah diterima / sudah punya | I23: =COUNTIF(L7:L21,"Diterima")+COUNTIF(L7:L21,"Sudah punya")&" dari "&COUNTA(C7:C21)&" item" -> 9 dari 15 item
A25: Tahap 2 dianggap selesai bila:
A26: ☐ | C26: ESP32 membaca meter via MAX3485 (Modbus FC03).
A27: ☐ | C27: SSR menyambung/melepas step sesuai algoritma hysteresis tanpa hunting.
A28: ☐ | C28: Relay menjalankan profil beban 12 menit.
A29: ☐ | C29: Panel 220 V terakit rapi di box, emergency stop berfungsi.
A30: ☐ | C30: Uji profil A/B (APFC mati vs hidup) berhasil 3× berturut.

Sheet Tahap 3
A1: TAHAP 3 — Kelengkapan demo & cadangan
A2: Kapan dipesan: | C2: Pesan Senin 12 Okt 2026, setelah pengumuman tim lolos.
A3: Tujuan: | C3: Memperkuat tampilan dan keandalan demo di depan juri.
A4: Qty, harga, dan Status diubah di sheet 'Daftar Belanja'; sheet ini ikut berubah otomatis.
A6: No | B6: No di Daftar Belanja | C6: Komponen | D6: Merek / Model / Kode seri | E6: Qty | F6: Satuan | G6: Harga satuan min (Rp) | H6: Harga satuan maks (Rp) | I6: Subtotal min (Rp) | J6: Subtotal maks (Rp) | K6: Harga Beli (RP) | L6: Status | M6: Link Tokopedia | N6: Link Shopee | O6: Alasan dibeli di tahap ini | P6: Catatan agar tidak salah beli
A7: 1 | B7: 6 | C7: ='Daftar Belanja'!C11 -> SSR satuan (cadangan) | D7: ='Daftar Belanja'!D11 -> Omron G3MB-202P (DC5V) | E7: ='Daftar Belanja'!F11 -> 2 | F7: ='Daftar Belanja'!G11 -> pcs | G7: ='Daftar Belanja'!H11 -> 15000 | H7: ='Daftar Belanja'!I11 -> 20000 | I7: ='Daftar Belanja'!J11 -> 30000 | J7: ='Daftar Belanja'!K11 -> 40000 | K7: ='Daftar Belanja'!N11 -> 72000 | L7: ='Daftar Belanja'!O11 -> Diterima | M7: Tokopedia | N7: Shopee | O7: Cadangan bila SSR rusak saat demo. | P7: =IF('Daftar Belanja'!R11="","",'Daftar Belanja'!R11) -> Pastikan kode -202P (zero-cross), BUKAN -202PL (tanpa zero-cross).
A8: 2 | B8: 9 | C8: ='Daftar Belanja'!C14 -> Modul microSD (log data cadangan) | D8: ='Daftar Belanja'!D14 -> Micro SD card module SPI (3,3 V / 5 V) | E8: ='Daftar Belanja'!F14 -> 1 | F8: ='Daftar Belanja'!G14 -> unit | G8: ='Daftar Belanja'!H14 -> 10000 | H8: ='Daftar Belanja'!I14 -> 25000 | I8: ='Daftar Belanja'!J14 -> 10000 | J8: ='Daftar Belanja'!K14 -> 25000 | K8: ='Daftar Belanja'!N14 -> 7500 | L8: ='Daftar Belanja'!O14 -> Diterima | M8: Tokopedia | N8: Shopee | O8: Log data cadangan bila Wi-Fi venue bermasalah. | P8: =IF('Daftar Belanja'!R14="","",'Daftar Belanja'!R14) -> Pin ESP32: SCK 18, MISO 19, MOSI 23, CS 5.
A9: 3 | B9: 10 | C9: ='Daftar Belanja'!C15 -> Kartu microSD | D9: ='Daftar Belanja'!D15 -> microSD 8–16 GB Class 10 (SanDisk/V-Gen) | E9: ='Daftar Belanja'!F15 -> 1 | F9: ='Daftar Belanja'!G15 -> pcs | G9: ='Daftar Belanja'!H15 -> 40000 | H9: ='Daftar Belanja'!I15 -> 70000 | I9: ='Daftar Belanja'!J15 -> 0 | J9: ='Daftar Belanja'!K15 -> 0 | K9: ='Daftar Belanja'!N15 -> 0 | L9: ='Daftar Belanja'!O15 -> Sudah punya | M9: Tokopedia | N9: Shopee | O9: Media penyimpanan modul microSD. | P9: =IF('Daftar Belanja'!R15="","",'Daftar Belanja'!R15) -> Format FAT32 sebelum dipakai.
A10: 4 | B10: 19 | C10: ='Daftar Belanja'!C24 -> Ballast magnetik (beban induktif tambahan) | D10: ='Daftar Belanja'!D24 -> Philips BTA 36W 220V (ballast trafo TL magnetik) | E10: ='Daftar Belanja'!F24 -> 1 | F10: ='Daftar Belanja'!G24 -> pcs | G10: ='Daftar Belanja'!H24 -> 90000 | H10: ='Daftar Belanja'!I24 -> 110000 | I10: ='Daftar Belanja'!J24 -> 90000 | J10: ='Daftar Belanja'!K24 -> 110000 | K10: ='Daftar Belanja'!N24 -> 0 | L10: ='Daftar Belanja'!O24 -> Belum | M10: Tokopedia | N10: Shopee | O10: Beban induktif tambahan agar demo lebih bervariasi. | P10: =IF('Daftar Belanja'!R24="","",'Daftar Belanja'!R24) -> Ballast MAGNETIK (trafo), bukan ballast elektronik. Wajib dipakai bersama lampu TL + starter.
A11: 5 | B11: 20 | C11: ='Daftar Belanja'!C25 -> Lampu TL set untuk ballast | D11: ='Daftar Belanja'!D25 -> Tabung TL-D 36W + starter S10 + kap/fitting TL 1×36W | E11: ='Daftar Belanja'!F25 -> 1 | F11: ='Daftar Belanja'!G25 -> set | G11: ='Daftar Belanja'!H25 -> 50000 | H11: ='Daftar Belanja'!I25 -> 100000 | I11: ='Daftar Belanja'!J25 -> 50000 | J11: ='Daftar Belanja'!K25 -> 100000 | K11: ='Daftar Belanja'!N25 -> 140000 | L11: ='Daftar Belanja'!O25 -> Diterima | M11: Tokopedia | N11: Shopee | O11: Pasangan ballast magnetik. | P11: =IF('Daftar Belanja'!R25="","",'Daftar Belanja'!R25) -> Bila kap bawaan punya kapasitor kompensasi, lepas kapasitornya agar beban tetap induktif.
A12: 6 | B12: 26 | C12: ='Daftar Belanja'!C31 -> Lampu indikator step & power | D12: ='Daftar Belanja'!D31 -> Pilot lamp LED AD16-22DS 220 VAC 22 mm (3 hijau + 1 merah) | E12: ='Daftar Belanja'!F31 -> 4 | F12: ='Daftar Belanja'!G31 -> pcs | G12: ='Daftar Belanja'!H31 -> 8000 | H12: ='Daftar Belanja'!I31 -> 15000 | I12: ='Daftar Belanja'!J31 -> 32000 | J12: ='Daftar Belanja'!K31 -> 60000 | K12: ='Daftar Belanja'!N31 -> 21000 | L12: ='Daftar Belanja'!O31 -> Diterima | M12: Tokopedia | N12: Shopee | O12: Visual untuk juri: step mana yang aktif. | P12: =IF('Daftar Belanja'!R31="","",'Daftar Belanja'!R31) -> Hijau dipasang paralel setelah tiap SSR — juri melihat step mana yang aktif.
A13: 7 | B13: 35 | C13: ='Daftar Belanja'!C40 -> Tang ampere (bukti fisik di demo) | D13: ='Daftar Belanja'!D40 -> UNI-T UT204+ True RMS AC/DC clamp meter | E13: ='Daftar Belanja'!F40 -> 1 | F13: ='Daftar Belanja'!G40 -> unit | G13: ='Daftar Belanja'!H40 -> 450000 | H13: ='Daftar Belanja'!I40 -> 700000 | I13: ='Daftar Belanja'!J40 -> 450000 | J13: ='Daftar Belanja'!K40 -> 700000 | K13: ='Daftar Belanja'!N40 -> 0 | L13: ='Daftar Belanja'!O40 -> Belum | M13: Tokopedia | N13: Shopee | O13: Bukti fisik arus turun di depan juri; juga untuk laporan teknis. | P13: =IF('Daftar Belanja'!R40="","",'Daftar Belanja'!R40) -> Dijepit di kabel L sebelum kapasitor: juri melihat arus turun saat step masuk. Lewati bila sudah punya.
C14: TOTAL TAHAP 3 | I14: =SUM(I7:I13) -> 662000 | J14: =SUM(J7:J13) -> 1035000 | K14: =SUM(K7:K13) -> 240500
C15: Item sudah diterima / sudah punya | I15: =COUNTIF(L7:L13,"Diterima")+COUNTIF(L7:L13,"Sudah punya")&" dari "&COUNTA(C7:C13)&" item" -> 5 dari 7 item
A17: Tahap 3 dianggap selesai bila:
A18: ☐ | C18: Lampu indikator step terpasang di pintu panel.
A19: ☐ | C19: Log microSD berjalan sebagai cadangan data.
A20: ☐ | C20: Tang ampere menunjukkan arus turun saat step masuk.
A21: ☐ | C21: Komponen cadangan (SSR, ESP32, HLK) dibawa ke Demo Day.

Sheet Ringkasan
A1: Ringkasan Anggaran Demo Day
A2: Semua angka dihitung otomatis dari sheet 'Daftar Belanja'.
A4: Kategori | B4: Jumlah item | C4: Total min (Rp) | D4: Total maks (Rp)
A5: A. Pengukuran & Kontrol | B5: =COUNTIF('Daftar Belanja'!$B$5:$B$41,A5) -> 11 | C5: =SUMIF('Daftar Belanja'!$B$5:$B$41,A5,'Daftar Belanja'!$J$5:$J$41) -> 1024000 | D5: =SUMIF('Daftar Belanja'!$B$5:$B$41,A5,'Daftar Belanja'!$K$5:$K$41) -> 1327000
A6: B. Bank Kapasitor | B6: =COUNTIF('Daftar Belanja'!$B$5:$B$41,A6) -> 7 | C6: =SUMIF('Daftar Belanja'!$B$5:$B$41,A6,'Daftar Belanja'!$J$5:$J$41) -> 140000 | D6: =SUMIF('Daftar Belanja'!$B$5:$B$41,A6,'Daftar Belanja'!$K$5:$K$41) -> 455000
A7: C. Beban Demo | B7: =COUNTIF('Daftar Belanja'!$B$5:$B$41,A7) -> 6 | C7: =SUMIF('Daftar Belanja'!$B$5:$B$41,A7,'Daftar Belanja'!$J$5:$J$41) -> 1105000 | D7: =SUMIF('Daftar Belanja'!$B$5:$B$41,A7,'Daftar Belanja'!$K$5:$K$41) -> 1495000
A8: D. Proteksi & Panel | B8: =COUNTIF('Daftar Belanja'!$B$5:$B$41,A8) -> 11 | C8: =SUMIF('Daftar Belanja'!$B$5:$B$41,A8,'Daftar Belanja'!$J$5:$J$41) -> 658000 | D8: =SUMIF('Daftar Belanja'!$B$5:$B$41,A8,'Daftar Belanja'!$K$5:$K$41) -> 1300000
A9: E. Alat Ukur & Perkakas | B9: =COUNTIF('Daftar Belanja'!$B$5:$B$41,A9) -> 2 | C9: =SUMIF('Daftar Belanja'!$B$5:$B$41,A9,'Daftar Belanja'!$J$5:$J$41) -> 450000 | D9: =SUMIF('Daftar Belanja'!$B$5:$B$41,A9,'Daftar Belanja'!$K$5:$K$41) -> 700000
A10: TOTAL | B10: =SUM(B5:B9) -> 37 | C10: =SUM(C5:C9) -> 3377000 | D10: =SUM(D5:D9) -> 5277000
A12: Prioritas | B12: Jumlah item | C12: Total min (Rp) | D12: Total maks (Rp)
A13: Wajib (termasuk cadangan wajib) | B13: =COUNTIF('Daftar Belanja'!$L$5:$L$41,E13) -> 25 | C13: =SUMIF('Daftar Belanja'!$L$5:$L$41,E13,'Daftar Belanja'!$J$5:$J$41) -> 2640000 | D13: =SUMIF('Daftar Belanja'!$L$5:$L$41,E13,'Daftar Belanja'!$K$5:$K$41) -> 4017000 | E13: Wajib*
A14: Disarankan | B14: =COUNTIF('Daftar Belanja'!$L$5:$L$41,E14) -> 7 | C14: =SUMIF('Daftar Belanja'!$L$5:$L$41,E14,'Daftar Belanja'!$J$5:$J$41) -> 647000 | D14: =SUMIF('Daftar Belanja'!$L$5:$L$41,E14,'Daftar Belanja'!$K$5:$K$41) -> 1025000 | E14: Disarankan
A15: Cadangan | B15: =COUNTIF('Daftar Belanja'!$L$5:$L$41,E15) -> 1 | C15: =SUMIF('Daftar Belanja'!$L$5:$L$41,E15,'Daftar Belanja'!$J$5:$J$41) -> 30000 | D15: =SUMIF('Daftar Belanja'!$L$5:$L$41,E15,'Daftar Belanja'!$K$5:$K$41) -> 40000 | E15: Cadangan
A16: Opsional | B16: =COUNTIF('Daftar Belanja'!$L$5:$L$41,E16) -> 3 | C16: =SUMIF('Daftar Belanja'!$L$5:$L$41,E16,'Daftar Belanja'!$J$5:$J$41) -> 60000 | D16: =SUMIF('Daftar Belanja'!$L$5:$L$41,E16,'Daftar Belanja'!$K$5:$K$41) -> 195000 | E16: Opsional
A18: Progres belanja
A19: Belum | B19: =COUNTIF('Daftar Belanja'!$O$5:$O$41,A19) -> 11
A20: Dipesan | B20: =COUNTIF('Daftar Belanja'!$O$5:$O$41,A20) -> 0
A21: Diterima | B21: =COUNTIF('Daftar Belanja'!$O$5:$O$41,A21) -> 21
A22: Sudah punya | B22: =COUNTIF('Daftar Belanja'!$O$5:$O$41,A22) -> 5
A26: Anggaran per tahap belanja
A27: Tahap | B27: Jumlah item | C27: Total min (Rp) | D27: Total maks (Rp) | E27: Kapan dipesan
A28: Tahap 1 | B28: =COUNTIF('Daftar Belanja'!$S$5:$S$41,F28) -> 14 | C28: =SUMIF('Daftar Belanja'!$S$5:$S$41,F28,'Daftar Belanja'!$J$5:$J$41) -> 2211000 | D28: =SUMIF('Daftar Belanja'!$S$5:$S$41,F28,'Daftar Belanja'!$K$5:$K$41) -> 3195000 | E28: Pesan hari ini, Senin 5 Okt 2026 (target tiba 7–8 Okt). | F28: 1
A29: Tahap 2 | B29: =COUNTIF('Daftar Belanja'!$S$5:$S$41,F29) -> 15 | C29: =SUMIF('Daftar Belanja'!$S$5:$S$41,F29,'Daftar Belanja'!$J$5:$J$41) -> 504000 | D29: =SUMIF('Daftar Belanja'!$S$5:$S$41,F29,'Daftar Belanja'!$K$5:$K$41) -> 1047000 | E29: Pesan Kamis–Jumat, 8–9 Okt 2026, setelah uji meja Tahap 1. | F29: 2
A30: Tahap 3 | B30: =COUNTIF('Daftar Belanja'!$S$5:$S$41,F30) -> 7 | C30: =SUMIF('Daftar Belanja'!$S$5:$S$41,F30,'Daftar Belanja'!$J$5:$J$41) -> 662000 | D30: =SUMIF('Daftar Belanja'!$S$5:$S$41,F30,'Daftar Belanja'!$K$5:$K$41) -> 1035000 | E30: Pesan Senin 12 Okt 2026, setelah pengumuman tim lolos. | F30: 3
A31: TOTAL | B31: =SUM(B28:B30) -> 36 | C31: =SUM(C28:C30) -> 3377000 | D31: =SUM(D28:D30) -> 5277000

Sheet Cek Sebelum Beli
A1: Cek sebelum checkout — kesalahan beli yang paling sering
A3: Meter DDSU666 | B3: Judul produk HARUS menyebut RS485/Modbus. Versi tanpa komunikasi (±Rp410 rb) tidak bisa dibaca ESP32.
A4: Modul RS485 | B4: MAX3485 (3,3 V), bukan MAX485 (5 V).
A5: SSR | B5: G3MB-202P (zero-cross). Hindari G3MB-202PL. Pilih modul 'high level trigger'.
A6: Kapasitor | B6: CBB60 / CBB65 tipe AC ≥ 450 VAC. Bukan ELCO, bukan kapasitor start CD60.
A7: Motor | B7: 1/4 HP 1 fasa, utamakan tipe kapasitor-start (kode YC). Tanyakan penjual apakah ada kapasitor run.
A8: Ballast | B8: Ballast MAGNETIK (trafo, berat), bukan ballast elektronik. Pakai bersama lampu TL + starter.
A9: Catu daya | B9: HLK-5M05 (5 W). HLK-PM01 (3 W) terlalu kecil.
A10: RCBO | B10: 6 A, 30 mA, 1P+N.
A11: Urutan beli | B11: Pesan dulu: DDSU666, motor, box panel (paling lama datang). Lalu komponen elektronik.
A12: Uji meja | B12: Begitu meter, motor, dan kapasitor datang: (1) 1 kapasitor saja → Q ≈ −91 VAr; (2) motor saja → catat Q; (3) motor + 1/2/3 kapasitor → Q turun bertahap. Pilih nilai µF final dari hasil langkah 2.
