Workbook

Sheet Template Tim
A1: FORMULIR PENGAJUAN BARANG PENDUKUNG PENGEMBANGAN PURWARUPA (PROTOTYPE)
A2: DeepTech for Smart-X Hackathon: Digitalisasi & Semikonduktor Berbasis AI Accelerator, Chip Design, dan Edge Intelligence
A4: Nama Tim | C4: Aku Anak Sehat | K4: Plafon Dana per Tim (diisi panitia)
A5: Nama Ketua Tim | C5: Marcel Suandi Tambing | K5: Total Pengajuan | M5: =SUM(J16:J65) -> 2552097
A6: No. WhatsApp Ketua/PIC Tim | C6: 6281286869644 | K6: Sisa / (Kelebihan) Plafon | M6: =IF(M4="","",M4-M5)
A7: Email Ketua/PIC Tim | C7: marcelsuanditambing@gmail.com | K7: Jumlah Item Diajukan | M7: =COUNTA(C16:C65) -> 44
A8: Judul Proposal / Purwarupa | C8: Modul Perhitungan Penggunaan Listrik Aktif-Reaktif Berbasis Edge-IoT Dengan Koreksi Faktor Daya Otomatis untuk Menekan Penalti kVarh Pelanggan Industri PLN | K8: Item Berpotensi Barang Modal | M8: =COUNTIF(N16:N65,"Berpotensi*") -> 0
A9: Track / Topik | C9: Smart Meter - Modul Perhitungan Penggunaan Listrik | K9: Total Disetujui Panitia | M9: =SUM(Q16:Q65) -> 0
K11: Status pengajuan | M11: =IF(M7=0,"Belum ada item","Siap diajukan") -> Siap diajukan
A12: Isi hanya sel KUNING. Sel ABU-ABU terisi otomatis. Sel HIJAU diisi panitia. Barang modal/aset (nilai > Rp5 juta & masa pakai > 1 tahun, atau dapat berfungsi mandiri) tidak dapat difasilitasi. Lihat sheet "Petunjuk Salin".
A14: DIISI OLEH PESERTA | O14: DIISI OLEH PANITIA
A15: No | B15: Nama Tim | C15: Nama Barang * | D15: Spesifikasi Teknis * (merek/tipe/ukuran/versi) | E15: Kategori * | F15: Fungsi dalam Purwarupa * (sesuai proposal) | G15: Jumlah * | H15: Satuan * | I15: Harga Satuan (Rp) * | J15: Total Harga (Rp) | K15: Link Toko / Referensi Harga * | L15: Prioritas * | M15: Sifat Barang * | N15: Cek Otomatis | O15: Status Verifikasi | P15: Jumlah Disetujui | Q15: Total Disetujui (Rp) | R15: Catatan Panitia
A16: =IF(C16="","",ROW()-15) -> 1 | B16: Aku Anak Sehat | C16: Meter energi 1 fasa Modbus | D16: CHINT DDSU666, RS485 Modbus RTU, 5(80) A, 230 V, kelas 1, DIN rail 2 modul | E16: Sensor / alat ukur | F16: Mengukur V, I, P, Q, PF, f, kWh beban secara real-time; dibaca ESP32 via Modbus RTU sebagai dasar algoritma koreksi faktor daya | G16: 1 | H16: unit | I16: 329999 | J16: =IF(OR(G16="",I16=""),"",G16*I16) -> 329999 | K16: https://www.tokopedia.com/listriknusantara/chint-ddsu666-single-phase-5-80-a-rs485-din-rail-meter-ip2w-220v | L16: Tinggi | M16: Habis pakai / komponen terpasang di purwarupa | N16: =IF(C16="","",IF(I16>5000000,"Berpotensi barang modal","OK - barang habis pakai")) -> OK - barang habis pakai | Q16: =IF(OR(P16="",I16=""),"",P16*I16)
A17: =IF(C17="","",ROW()-15) -> 2 | B17: Aku Anak Sehat | C17: Modul TTL–RS485 auto-direction | D17: Modul merah MAX13487EESA, 5 V, terminal A/B/GND, jumper terminasi 120 Ω | E17: Modul komunikasi | F17: Antarmuka RS485 antara ESP32 dan meter DDSU666 (1 terpasang, 1 cadangan) | G17: 2 | H17: pcs | I17: 68266 | J17: =IF(OR(G17="",I17=""),"",G17*I17) -> 136532 | K17: https://www.tokopedia.com/tekno-kreasi-elektronik/max3485-module-ttl-to-rs485-usart-communication | L17: Tinggi | M17: Habis pakai / komponen terpasang di purwarupa | N17: =IF(C17="","",IF(I17>5000000,"Berpotensi barang modal","OK - barang habis pakai")) -> OK - barang habis pakai | Q17: =IF(OR(P17="",I17=""),"",P17*I17)
A18: =IF(C18="","",ROW()-15) -> 3 | B18: Aku Anak Sehat | C18: Modul TTL–RS485 HW-0519 | D18: HW-0519, MAX485ESA + 74HC04 (auto-direction), 3,3–5 V | E18: Modul komunikasi | F18: Modul RS485 cadangan untuk komunikasi ESP32–meter saat demo | G18: 2 | H18: pcs | I18: 15000 | J18: =IF(OR(G18="",I18=""),"",G18*I18) -> 30000 | K18: https://www.tokopedia.com/search?st=product&q=hw-0519+ttl+to+rs485+auto+direction | L18: Rendah | M18: Habis pakai / komponen cadangan purwarupa | N18: =IF(C18="","",IF(I18>5000000,"Berpotensi barang modal","OK - barang habis pakai")) -> OK - barang habis pakai | Q18: =IF(OR(P18="",I18=""),"",P18*I18)
A19: =IF(C19="","",ROW()-15) -> 4 | B19: Aku Anak Sehat | C19: Adaptor USB–RS485 | D19: Konverter USB to RS485 chip CH340 | E19: Modul komunikasi | F19: Membaca dan mengonfigurasi meter dari laptop saat uji meja dan kalibrasi (logger CSV) | G19: 1 | H19: pcs | I19: 37000 | J19: =IF(OR(G19="",I19=""),"",G19*I19) -> 37000 | K19: https://www.tokopedia.com/search?st=product&q=usb+to+rs485+ch340 | L19: Sedang | M19: Habis pakai / aksesori pengujian purwarupa | N19: =IF(C19="","",IF(I19>5000000,"Berpotensi barang modal","OK - barang habis pakai")) -> OK - barang habis pakai | Q19: =IF(OR(P19="",I19=""),"",P19*I19)
A20: =IF(C20="","",ROW()-15) -> 5 | B20: Aku Anak Sehat | C20: Mikrokontroler ESP32 (edge controller) | D20: ESP32 DevKit ESP-WROOM-32D, 38 pin, Wi-Fi + BLE, USB CP2102 | E20: Mikrokontroler / dev board | F20: Unit pemroses edge: membaca meter (Modbus), menjalankan algoritma koreksi faktor daya, mengendalikan SSR/relay, LCD, log dan koneksi Wi-Fi/MQTT ke dashboard (1 terpasang, 1 cadangan) | G20: 2 | H20: unit | I20: 85000 | J20: =IF(OR(G20="",I20=""),"",G20*I20) -> 170000 | K20: https://www.tokopedia.com/sensorku-bekasi/esp32-esp-32-wroom-32-doit-devkit-v1-usb-c | L20: Tinggi | M20: Habis pakai / komponen terpasang di purwarupa | N20: =IF(C20="","",IF(I20>5000000,"Berpotensi barang modal","OK - barang habis pakai")) -> OK - barang habis pakai | Q20: =IF(OR(P20="",I20=""),"",P20*I20)
A21: =IF(C21="","",ROW()-15) -> 6 | B21: Aku Anak Sehat | C21: Shield / expansion board ESP32 | D21: Base board ESP32 38 pin, header S-V-G, jumper V 5 V/3,3 V, input USB-C & DC | E21: Mikrokontroler / dev board | F21: Dudukan ESP32 dan distribusi pin sinyal/catu ke modul SSR, relay, RS485, LCD dan microSD | G21: 1 | H21: pcs | I21: 35000 | J21: =IF(OR(G21="",I21=""),"",G21*I21) -> 35000 | K21: https://www.tokopedia.com/search?st=product&q=esp32+expansion+board+shield+38+pin | L21: Sedang | M21: Habis pakai / komponen terpasang di purwarupa | N21: =IF(C21="","",IF(I21>5000000,"Berpotensi barang modal","OK - barang habis pakai")) -> OK - barang habis pakai | Q21: =IF(OR(P21="",I21=""),"",P21*I21)
A22: =IF(C22="","",ROW()-15) -> 7 | B22: Aku Anak Sehat | C22: Level shifter dua arah 4 kanal | D22: Logic level converter BSS138, 3,3 V ↔ 5 V, 4 kanal | E22: Modul elektronik | F22: Penyesuai level I²C (LCD 5 V) dan UART (modul RS485 5 V) ke ESP32 3,3 V; 1 terpasang, 1 cadangan | G22: 2 | H22: pcs | I22: 4658 | J22: =IF(OR(G22="",I22=""),"",G22*I22) -> 9316 | K22: https://www.tokopedia.com/search?st=product&q=i2c+logic+level+converter+bi-directional+5v+3.3v+4+channel | L22: Tinggi | M22: Habis pakai / komponen terpasang di purwarupa | N22: =IF(C22="","",IF(I22>5000000,"Berpotensi barang modal","OK - barang habis pakai")) -> OK - barang habis pakai | Q22: =IF(OR(P22="",I22=""),"",P22*I22)
A23: =IF(C23="","",ROW()-15) -> 8 | B23: Aku Anak Sehat | C23: LCD 20×4 + modul I²C | D23: LCD 2004A biru + backpack I²C PCF8574 (alamat 0x27), 5 V | E23: Modul elektronik | F23: Tampilan lokal di pintu panel: V, I, P, Q, PF, status step, mode dan alarm | G23: 1 | H23: pcs | I23: 60000 | J23: =IF(OR(G23="",I23=""),"",G23*I23) -> 60000 | K23: https://www.tokopedia.com/search?st=product&q=lcd+2004+i2c+20x4+biru | L23: Tinggi | M23: Habis pakai / komponen terpasang di purwarupa | N23: =IF(C23="","",IF(I23>5000000,"Berpotensi barang modal","OK - barang habis pakai")) -> OK - barang habis pakai | Q23: =IF(OR(P23="",I23=""),"",P23*I23)
A24: =IF(C24="","",ROW()-15) -> 9 | B24: Aku Anak Sehat | C24: Modul microSD SPI | D24: Micro SD card module SPI, regulator 3,3 V + buffer level onboard | E24: Modul elektronik | F24: Penyimpanan log data cadangan (CSV tiap 10 s) bila Wi-Fi/laptop tidak tersedia | G24: 1 | H24: pcs | I24: 7500 | J24: =IF(OR(G24="",I24=""),"",G24*I24) -> 7500 | K24: https://www.tokopedia.com/focuscamerashop/microsd-module-for-arduino-3-3v-esp8266-esp32-tf-card-micro-sd-shield | L24: Sedang | M24: Habis pakai / komponen terpasang di purwarupa | N24: =IF(C24="","",IF(I24>5000000,"Berpotensi barang modal","OK - barang habis pakai")) -> OK - barang habis pakai | Q24: =IF(OR(P24="",I24=""),"",P24*I24)
A25: =IF(C25="","",ROW()-15) -> 10 | B25: Aku Anak Sehat | C25: Kartu microSD | D25: microSD 32 GB SDHC Class 10, format FAT32 | E25: Modul elektronik | F25: Media penyimpanan log CSV harian dan event pada modul microSD | G25: 1 | H25: pcs | I25: 55000 | J25: =IF(OR(G25="",I25=""),"",G25*I25) -> 55000 | K25: https://www.tokopedia.com/search?st=product&q=microsd%2032gb%20sandisk%20class%2010 | L25: Sedang | M25: Habis pakai / komponen terpasang di purwarupa | N25: =IF(C25="","",IF(I25>5000000,"Berpotensi barang modal","OK - barang habis pakai")) -> OK - barang habis pakai | Q25: =IF(OR(P25="",I25=""),"",P25*I25)
A26: =IF(C26="","",ROW()-15) -> 11 | B26: Aku Anak Sehat | C26: Modul SSR 4 kanal high-level trigger | D26: Omron G3MB-202P zero-cross, 2 A 240 VAC per kanal, input 5 V, sekring per kanal | E26: Modul elektronik / aktuator | F26: Saklar elektronik zero-cross untuk menyambung/melepas 3 step bank kapasitor sesuai perintah algoritma | G26: 1 | H26: pcs | I26: 60250 | J26: =IF(OR(G26="",I26=""),"",G26*I26) -> 60250 | K26: https://www.tokopedia.com/search?st=product&q=ssr+4+channel+g3mb-202p+high+level+trigger | L26: Tinggi | M26: Habis pakai / komponen terpasang di purwarupa | N26: =IF(C26="","",IF(I26>5000000,"Berpotensi barang modal","OK - barang habis pakai")) -> OK - barang habis pakai | Q26: =IF(OR(P26="",I26=""),"",P26*I26)
A27: =IF(C27="","",ROW()-15) -> 12 | B27: Aku Anak Sehat | C27: SSR satuan (cadangan) | D27: Omron G3MB-202P DC 5 V, zero-cross, 2 A 240 VAC, SIP-4 | E27: Modul elektronik / aktuator | F27: Pengganti cepat bila salah satu kanal SSR rusak saat pengujian/demo | G27: 2 | H27: pcs | I27: 36000 | J27: =IF(OR(G27="",I27=""),"",G27*I27) -> 72000 | K27: https://www.tokopedia.com/mkontrol/g3mb-202p-5v-dc-ac-ssr-in-5vdc-out-240vac-2a-solid-state-relay-omron | L27: Rendah | M27: Habis pakai / komponen cadangan purwarupa | N27: =IF(C27="","",IF(I27>5000000,"Berpotensi barang modal","OK - barang habis pakai")) -> OK - barang habis pakai | Q27: =IF(OR(P27="",I27=""),"",P27*I27)
... A59: =IF(C59="","",ROW()-15) -> 44 | B59: Aku Anak Sehat | C59: Multimeter digital | D59: UNI-T UT33D+ (V, A, Ω, kontinuitas) | E59: Perkakas habis pakai | F59: Pengecekan tegangan sisa kapasitor, kontinuitas pengawatan dan commissioning panel | G59: 1 | H59: unit | I59: 150000 | J59: =IF(OR(G59="",I59=""),"",G59*I59) -> 150000 | K59: https://www.tokopedia.com/search?st=product&q=multimeter%20uni-t%20ut33d%2B | L59: Rendah | M59: Habis pakai / alat bantu pengujian purwarupa | N59: =IF(C59="","",IF(I59>5000000,"Berpotensi barang modal","OK - barang habis pakai")) -> OK - barang habis pakai | Q59: =IF(OR(P59="",I59=""),"",P59*I59)
A60: =IF(C60="","",ROW()-15) | J60: =IF(OR(G60="",I60=""),"",G60*I60) | N60: =IF(C60="","",IF(I60>5000000,"Berpotensi barang modal","OK - barang habis pakai")) | Q60: =IF(OR(P60="",I60=""),"",P60*I60)
A61: =IF(C61="","",ROW()-15) | J61: =IF(OR(G61="",I61=""),"",G61*I61) | N61: =IF(C61="","",IF(I61>5000000,"Berpotensi barang modal","OK - barang habis pakai")) | Q61: =IF(OR(P61="",I61=""),"",P61*I61)
A62: =IF(C62="","",ROW()-15) | J62: =IF(OR(G62="",I62=""),"",G62*I62) | N62: =IF(C62="","",IF(I62>5000000,"Berpotensi barang modal","OK - barang habis pakai")) | Q62: =IF(OR(P62="",I62=""),"",P62*I62)
A63: =IF(C63="","",ROW()-15) | J63: =IF(OR(G63="",I63=""),"",G63*I63) | N63: =IF(C63="","",IF(I63>5000000,"Berpotensi barang modal","OK - barang habis pakai")) | Q63: =IF(OR(P63="",I63=""),"",P63*I63)
A64: =IF(C64="","",ROW()-15) | J64: =IF(OR(G64="",I64=""),"",G64*I64) | N64: =IF(C64="","",IF(I64>5000000,"Berpotensi barang modal","OK - barang habis pakai")) | Q64: =IF(OR(P64="",I64=""),"",P64*I64)
A65: =IF(C65="","",ROW()-15) | J65: =IF(OR(G65="",I65=""),"",G65*I65) | N65: =IF(C65="","",IF(I65>5000000,"Berpotensi barang modal","OK - barang habis pakai")) | Q65: =IF(OR(P65="",I65=""),"",P65*I65)
A67: Keterangan:
A68: Sel harga satuan jingga = harga ESTIMASI (ganti dengan harga nota). Sel biru muda = barang milik tim dengan harga referensi pasar.
A69: Nilai pada kolom Kategori, Satuan, Prioritas dan Sifat Barang disesuaikan dengan pilihan dropdown di formulir panitia bila berbeda.

Sheet Rincian & Bukti
A1: No | B1: Kode di panel | C1: Nama Barang | D1: Jumlah | E1: Satuan | F1: Harga Satuan (Rp) | G1: Total (Rp) | H1: Sumber harga | I1: Status barang | J1: Bukti foto di repo (folder Gambar/) | K1: Catatan
A2: 1 | B2: P1 | C2: ='Template Tim'!C16 -> Meter energi 1 fasa Modbus | D2: ='Template Tim'!G16 -> 1 | E2: ='Template Tim'!H16 -> unit | F2: ='Template Tim'!I16 -> 329999 | G2: =D2*F2 -> 329999 | H2: Nota | I2: Diterima | J2: Gambar/ (8–9 Okt), IMG_20261013_225503
A3: 2 | B3: A4 | C3: ='Template Tim'!C17 -> Modul TTL–RS485 auto-direction | D3: ='Template Tim'!G17 -> 2 | E3: ='Template Tim'!H17 -> pcs | F3: ='Template Tim'!I17 -> 68266 | G3: =D3*F3 -> 136532 | H3: Nota | I3: Diterima | J3: MVIMG_20261012_183011, MVIMG_20261012_183045 | K3: Nota versi 1: Rp136.532 untuk 2 pcs (judul toko: MAX3485)
A4: 3 | B4: A4' | C4: ='Template Tim'!C18 -> Modul TTL–RS485 HW-0519 | D4: ='Template Tim'!G18 -> 2 | E4: ='Template Tim'!H18 -> pcs | F4: ='Template Tim'!I18 -> 15000 | G4: =D4*F4 -> 30000 | H4: Estimasi | I4: Diterima | J4: MVIMG_20261013_123702, MVIMG_20261013_123725
A5: 4 | B5: — | C5: ='Template Tim'!C19 -> Adaptor USB–RS485 | D5: ='Template Tim'!G19 -> 1 | E5: ='Template Tim'!H19 -> pcs | F5: ='Template Tim'!I19 -> 37000 | G5: =D5*F5 -> 37000 | H5: Nota | I5: Diterima | J5: Gambar/ (9 Okt)
A6: 5 | B6: A1 | C6: ='Template Tim'!C20 -> Mikrokontroler ESP32 (edge controller) | D6: ='Template Tim'!G20 -> 2 | E6: ='Template Tim'!H20 -> unit | F6: ='Template Tim'!I20 -> 85000 | G6: =D6*F6 -> 170000 | H6: Referensi | I6: Milik sendiri | J6: IMG_20261018_224917 | K6: Barang milik tim; harga mengikuti referensi pasar (contoh panitia Rp85.000)
A7: 6 | B7: A1' | C7: ='Template Tim'!C21 -> Shield / expansion board ESP32 | D7: ='Template Tim'!G21 -> 1 | E7: ='Template Tim'!H21 -> pcs | F7: ='Template Tim'!I21 -> 35000 | G7: =D7*F7 -> 35000 | H7: Estimasi | I7: Diterima | J7: IMG_20261018_224917
A8: 7 | B8: A7 | C8: ='Template Tim'!C22 -> Level shifter dua arah 4 kanal | D8: ='Template Tim'!G22 -> 2 | E8: ='Template Tim'!H22 -> pcs | F8: ='Template Tim'!I22 -> 4658 | G8: =D8*F8 -> 9316 | H8: Nota | I8: Diterima | J8: IMG_20261015_143818, IMG_20261016_210926 | K8: Harga dari screenshot toko (Rp4.658/pcs)
A9: 8 | B9: A5 | C9: ='Template Tim'!C23 -> LCD 20×4 + modul I²C | D9: ='Template Tim'!G23 -> 1 | E9: ='Template Tim'!H23 -> pcs | F9: ='Template Tim'!I23 -> 60000 | G9: =D9*F9 -> 60000 | H9: Estimasi | I9: Diterima | J9: IMG_20261018_224926
A10: 9 | B10: A6 | C10: ='Template Tim'!C24 -> Modul microSD SPI | D10: ='Template Tim'!G24 -> 1 | E10: ='Template Tim'!H24 -> pcs | F10: ='Template Tim'!I24 -> 7500 | G10: =D10*F10 -> 7500 | H10: Nota | I10: Diterima | J10: IMG_20261018_224917
A11: 10 | B11: A6' | C11: ='Template Tim'!C25 -> Kartu microSD | D11: ='Template Tim'!G25 -> 1 | E11: ='Template Tim'!H25 -> pcs | F11: ='Template Tim'!I25 -> 55000 | G11: =D11*F11 -> 55000 | H11: Referensi | I11: Milik sendiri | J11: — | K11: Barang milik tim; harga referensi pasar
A12: 11 | B12: A3 | C12: ='Template Tim'!C26 -> Modul SSR 4 kanal high-level trigger | D12: ='Template Tim'!G26 -> 1 | E12: ='Template Tim'!H26 -> pcs | F12: ='Template Tim'!I26 -> 60250 | G12: =D12*F12 -> 60250 | H12: Estimasi | I12: Diterima | J12: IMG_20261013_225444 | K12: Harga mengikuti nota pembelian SSR pertama (Rp60.250); sesuaikan dengan nota modul high-level
A13: 12 | B13: A3' | C13: ='Template Tim'!C27 -> SSR satuan (cadangan) | D13: ='Template Tim'!G27 -> 2 | E13: ='Template Tim'!H27 -> pcs | F13: ='Template Tim'!I27 -> 36000 | G13: =D13*F13 -> 72000 | H13: Nota | I13: Diterima | J13: Gambar/ (9 Okt) | K13: Nota versi 1: Rp72.000 untuk 2 pcs
A14: 13 | B14: A2 | C14: ='Template Tim'!C28 -> Modul relay 4 kanal 5 V | D14: ='Template Tim'!G28 -> 1 | E14: ='Template Tim'!H28 -> pcs | F14: ='Template Tim'!I28 -> 35500 | G14: =D14*F14 -> 35500 | H14: Nota | I14: Diterima | J14: IMG_20261013_225503
A15: 14 | B15: G1 | C15: ='Template Tim'!C29 -> Power supply 5 V 5 A | D15: ='Template Tim'!G29 -> 1 | E15: ='Template Tim'!H29 -> pcs | F15: ='Template Tim'!I29 -> 30000 | G15: =D15*F15 -> 30000 | H15: Nota | I15: Diterima | J15: MVIMG_20261013_175923, MVIMG_20261013_180124
A16: 15 | B16: C1–C2 | C16: ='Template Tim'!C30 -> Kapasitor AC step 6 µF | D16: ='Template Tim'!G30 -> 4 | E16: ='Template Tim'!H30 -> pcs | F16: ='Template Tim'!I30 -> 15000 | G16: =D16*F16 -> 60000 | H16: Nota | I16: Diterima | J16: Gambar/ (9 Okt) | K16: Nota versi 1: Rp60.000 untuk 4 pcs
A17: 16 | B17: C3 | C17: ='Template Tim'!C31 -> Kapasitor AC step 4 µF | D17: ='Template Tim'!G31 -> 1 | E17: ='Template Tim'!H31 -> pcs | F17: ='Template Tim'!I31 -> 15000 | G17: =D17*F17 -> 15000 | H17: Estimasi | I17: Akan dibeli | J17: — | K17: Kapasitor 4 µF bekas terukur hanya ±1 µF (rusak) pada uji 18 Okt
A18: 17 | B18: R | C18: ='Template Tim'!C32 -> Resistor pembuang muatan | D18: ='Template Tim'!G32 -> 10 | E18: ='Template Tim'!H32 -> pcs | F18: ='Template Tim'!I32 -> 1000 | G18: =D18*F18 -> 10000 | H18: Nota | I18: Diterima | J18: — | K18: Nota versi 1: Rp10.000 untuk 10 pcs
A19: 18 | B19: — | C19: ='Template Tim'!C33 -> Kapasitor filter 100 nF | D19: ='Template Tim'!G33 -> 2 | E19: ='Template Tim'!H33 -> pcs | F19: ='Template Tim'!I33 -> 1500 | G19: =D19*F19 -> 3000 | H19: Estimasi | I19: Diterima | J19: IMG_20261015_143827, IMG_20261016_211143
A20: 19 | B20: — | C20: ='Template Tim'!C34 -> Elco 1000 µF/16 V | D20: ='Template Tim'!G34 -> 1 | E20: ='Template Tim'!H34 -> pcs | F20: ='Template Tim'!I34 -> 2000 | G20: =D20*F20 -> 2000 | H20: Estimasi | I20: Akan dibeli | J20: — | K20: Cek: sudah punya atau perlu dibeli
A21: 20 | B21: Q1 | C21: ='Template Tim'!C35 -> RCBO 1P+N | D21: ='Template Tim'!G35 -> 1 | E21: ='Template Tim'!H35 -> pcs | F21: ='Template Tim'!I35 -> 110000 | G21: =D21*F21 -> 110000 | H21: Nota | I21: Diterima | J21: IMG_20261013_225503
A22: 21 | B22: Q2 | C22: ='Template Tim'!C36 -> MCB 1P beban | D22: ='Template Tim'!G36 -> 1 | E22: ='Template Tim'!H36 -> pcs | F22: ='Template Tim'!I36 -> 45000 | G22: =D22*F22 -> 45000 | H22: Estimasi | I22: Diterima | J22: IMG_20261018_224917
A23: 22 | B23: F1–F4 | C23: ='Template Tim'!C37 -> Rumah sekring DIN | D23: ='Template Tim'!G37 -> 4 | E23: ='Template Tim'!H37 -> pcs | F23: ='Template Tim'!I37 -> 20000 | G23: =D23*F23 -> 80000 | H23: Nota | I23: Diterima | J23: IMG_20261013_225503 | K23: Nota versi 1: Rp80.000 untuk 4 pcs
A24: 23 | B24: — | C24: ='Template Tim'!C38 -> Sekring tabung 10×38 mm | D24: ='Template Tim'!G38 -> 10 | E24: ='Template Tim'!H38 -> pcs | F24: ='Template Tim'!I38 -> 4000 | G24: =D24*F24 -> 40000 | H24: Nota | I24: Diterima | J24: — | K24: Nota versi 1: Rp40.000 untuk 10 pcs; pastikan ukuran 10×38 mm
A25: 24 | B25: S0 | C25: ='Template Tim'!C39 -> Tombol darurat (emergency stop) | D25: ='Template Tim'!G39 -> 1 | E25: ='Template Tim'!H39 -> pcs | F25: ='Template Tim'!I39 -> 20000 | G25: =D25*F25 -> 20000 | H25: Nota | I25: Diterima | J25: MVIMG_20261013_123550, MVIMG_20261013_123613
A26: 25 | B26: H1–H3 | C26: ='Template Tim'!C40 -> Lampu pilot hijau | D26: ='Template Tim'!G40 -> 3 | E26: ='Template Tim'!H40 -> pcs | F26: ='Template Tim'!I40 -> 7000 | G26: =D26*F26 -> 21000 | H26: Nota | I26: Diterima | J26: MVIMG_20261013_123631 | K26: Nota versi 1: Rp21.000
A27: 26 | B27: — | C27: ='Template Tim'!C41 -> Box panel besi | D27: ='Template Tim'!G41 -> 1 | E27: ='Template Tim'!H41 -> unit | F27: ='Template Tim'!I41 -> 155000 | G27: =D27*F27 -> 155000 | H27: Nota | I27: Diterima | J27: IMG_20261018_224839
A28: 27 | B28: — | C28: ='Template Tim'!C42 -> Rel DIN | D28: ='Template Tim'!G42 -> 1 | E28: ='Template Tim'!H42 -> batang | F28: ='Template Tim'!I42 -> 18000 | G28: =D28*F28 -> 18000 | H28: Nota | I28: Diterima | J28: IMG_20261018_224917
A29: 28 | B29: X1 | C29: ='Template Tim'!C43 -> Terminal blok DIN | D29: ='Template Tim'!G43 -> 1 | E29: ='Template Tim'!H43 -> set | F29: ='Template Tim'!I43 -> 35000 | G29: =D29*F29 -> 35000 | H29: Nota | I29: Diterima | J29: IMG_20261018_224917 | K29: Nota versi 1: Rp35.000 (20 pcs)
A30: 29 | B30: X1' | C30: ='Template Tim'!C44 -> Terminal barrier 6 jalur | D30: ='Template Tim'!G44 -> 1 | E30: ='Template Tim'!H44 -> pcs | F30: ='Template Tim'!I44 -> 10000 | G30: =D30*F30 -> 10000 | H30: Estimasi | I30: Diterima | J30: IMG_20261013_225503
A31: 30 | B31: — | C31: ='Template Tim'!C45 -> Kabel panel NYAF | D31: ='Template Tim'!G45 -> 30 | E31: ='Template Tim'!H45 -> meter | F31: ='Template Tim'!I45 -> 4000 | G31: =D31*F31 -> 120000 | H31: Estimasi | I31: Diterima | J31: IMG_20261018_224904
A32: 31 | B32: — | C32: ='Template Tim'!C46 -> Kabel sumber + steker | D32: ='Template Tim'!G46 -> 1 | E32: ='Template Tim'!H46 -> set | F32: ='Template Tim'!I46 -> 45000 | G32: =D32*F32 -> 45000 | H32: Estimasi | I32: Diterima | J32: IMG_20261018_224844
A33: 32 | B33: — | C33: ='Template Tim'!C47 -> Kabel papan beban | D33: ='Template Tim'!G47 -> 5 | E33: ='Template Tim'!H47 -> meter | F33: ='Template Tim'!I47 -> 8000 | G33: =D33*F33 -> 40000 | H33: Estimasi | I33: Diterima | J33: IMG_20261018_224829
A34: 33 | B34: — | C34: ='Template Tim'!C48 -> Kabel jumper dupont | D34: ='Template Tim'!G48 -> 1 | E34: ='Template Tim'!H48 -> set | F34: ='Template Tim'!I48 -> 15000 | G34: =D34*F34 -> 15000 | H34: Estimasi | I34: Diterima | J34: IMG_20261018_224917
A35: 34 | B35: — | C35: ='Template Tim'!C49 -> Kabel komunikasi RS485 | D35: ='Template Tim'!G49 -> 2 | E35: ='Template Tim'!H49 -> meter | F35: ='Template Tim'!I49 -> 5000 | G35: =D35*F35 -> 10000 | H35: Referensi | I35: Milik sendiri | J35: IMG_20261018_224917 | K35: Barang milik tim; harga referensi pasar
A36: 35 | B36: — | C36: ='Template Tim'!C50 -> PCB lubang (perforated board) | D36: ='Template Tim'!G50 -> 1 | E36: ='Template Tim'!H50 -> lembar | F36: ='Template Tim'!I50 -> 10000 | G36: =D36*F36 -> 10000 | H36: Estimasi | I36: Diterima | J36: IMG_20261016_211234
A37: 36 | B37: — | C37: ='Template Tim'!C51 -> Spacer nylon M3 + baut + mur | D37: ='Template Tim'!G51 -> 1 | E37: ='Template Tim'!H51 -> set | F37: ='Template Tim'!I51 -> 20000 | G37: =D37*F37 -> 20000 | H37: Estimasi | I37: Diterima | J37: IMG_20261016_211307
A38: 37 | B38: — | C38: ='Template Tim'!C52 -> Aksesoris pengawatan | D38: ='Template Tim'!G52 -> 1 | E38: ='Template Tim'!H52 -> paket | F38: ='Template Tim'!I52 -> 30000 | G38: =D38*F38 -> 30000 | H38: Estimasi | I38: Diterima | J38: IMG_20261018_224904
A39: 38 | B39: — | C39: ='Template Tim'!C53 -> Mata bor / step drill | D39: ='Template Tim'!G53 -> 1 | E39: ='Template Tim'!H53 -> pcs | F39: ='Template Tim'!I53 -> 35000 | G39: =D39*F39 -> 35000 | H39: Estimasi | I39: Dalam pengiriman | J39: —
A40: 39 | B40: E1–E2 | C40: ='Template Tim'!C54 -> Lampu TL lengkap | D40: ='Template Tim'!G54 -> 2 | E40: ='Template Tim'!H54 -> set | F40: ='Template Tim'!I54 -> 70000 | G40: =D40*F40 -> 140000 | H40: Nota | I40: Diterima | J40: IMG_20261013_222912, IMG_20261013_222951 | K40: Nota versi 1: Rp140.000; cek apakah untuk 2 set
...

Sheet Tidak Diajukan
A1: No | B1: Barang | C1: Jumlah | D1: Alasan tidak diajukan | E1: Keterangan
A2: 1 | B2: Laptop (broker MQTT + dashboard) | C2: 1 unit | D2: Barang modal / berfungsi mandiri | E2: —
A3: 2 | B3: Hi-Link HLK-5M05 | C3: 2 pcs (Rp58.500) | D3: Tidak dipakai — diganti PSU S-25-5 tertutup demi keselamatan | E3: Simpan sebagai cadangan
A4: 3 | B4: Modul SSR 4 kanal low-level trigger | C4: 1 pcs | D4: Salah beli (tidak kompatibel langsung dengan logika ESP32), diganti high-level | E4: Cadangan
A5: 4 | B5: Kapasitor CBB60 4 µF bekas (2009) | C5: 1 pcs | D5: Rusak — terukur ±0,8–1,2 µF pada uji 18 Okt | E5: Diganti kapasitor baru (sudah masuk daftar)
A6: 5 | B6: Motor induksi 1/4 HP, ballast BTA 36 W, halogen 300 W + rumah lampu, CBB60 8 µF | C6: — | D6: Batal — skenario beban diganti lampu TL + kompresor kulkas | E6: Tidak dibeli
A7: 6 | B7: Tang ampere UNI-T UT204+ | C7: 1 unit | D7: Alat ukur mandiri (barang modal) | E7: Tidak dibeli

Sheet Petunjuk Salin
A1: CARA MENYALIN KE FORMULIR PANITIA (Google Sheets, tab "Aku Anak Sehat")
A2: 1. Cek dulu sel harga berwarna jingga di sheet Template Tim (harga estimasi) dan ganti dengan harga nota/toko.
A3: 2. Di sheet Template Tim, blok sel B16 sampai M59 (Nama Tim s.d. Sifat Barang), lalu Copy.
A4: Kolom J (Total Harga) ikut tersalin sebagai angka; bila formulir panitia mengisi kolom J otomatis, salin dua blok: B–I lalu K–M.
A5: 3. Di formulir panitia, klik sel B16 lalu tempel sebagai NILAI SAJA: Ctrl+Shift+V (Paste values only) agar format dan dropdown panitia tidak rusak.
A6: 4. Periksa kolom Kategori, Satuan, Prioritas dan Sifat Barang: bila muncul tanda segitiga merah (tidak sesuai dropdown), pilih ulang opsi terdekat dari dropdown.
A7: 5. Pastikan Total Pengajuan di formulir panitia sama dengan Total Pengajuan di sheet ini (sel M5).
A8: 6. Barang yang tidak diajukan beserta alasannya ada di sheet Tidak Diajukan; bukti foto tiap barang ada di repo (folder Gambar/), lihat sheet Rincian & Bukti.
